Workbook

Sheet Simulasi
A1: Istimewa | B1: =COUNTIF($E$10:$E$43,A1)
A2: Baik Sekali | B2: =COUNTIF($E$10:$E$43,A2)
A3: Baik | B3: =COUNTIF($E$10:$E$43,A3)
A4: Cukup | B4: =COUNTIF($E$10:$E$43,A4)
A5: Kurang | B5: =COUNTIF($E$10:$E$43,A5)
O6: 0.85 | P6: 0.357 | Q6: 0.2465 | R6: 0.2465 | S6: 4 | T6: 8 | U6: 10 | V6: 13 | AE6: 0.3 | AH6: 0.3 | AK6: 0.4 | AN6: 0.5 | AQ6: 0.95 | AT6: 0.3 | AW6: 2 | AX6: 4 | AY6: 15 | AZ6: 48 | BA6: 96 | BL6: 0.3 | BO6: 0.3 | BR6: 0.4
A7: Regional | B7: NOP | C7: Rank | D7: Total KPI | E7: Category | F7: Bonus | G7: KPI AVAIL | H7: AVAILABILITY | O7: KPI Ticket Handling | S7: INCIDENT HANDLING | AW7: EVENT HANDLING | BU7: Activity & Alarm Handling
H8: Class Diamond | I8: Class Platinum | J8: Class Gold | K8: Class Silver | L8: Class Bronze | M8: Achieved Target Availability | N8: Total Score KPI Availability | O8: Total | P8: KPI Incident | Q8: KPI Event | R8: KPI Act | S8: MTTR P90 | W8: Skor | AA8: KPI | AE8: TO High Crit Maj | AF8: Skor | AG8: KPI | AH8: TO Low Min Low | AI8: Skor | AJ8: KPI | AK8: Visit | AL8: Skor | AM8: KPI | AN8: Top 5 | AO8: Skor | AP8: KPI | AQ8: Closing | AR8: Skor | AS8: KPI | AT8: RCA Validation | AU8: Skor | AV8: KPI | AW8: MTTR P90 | BB8: Skor | BG8: KPI | BL8: TO High Crit Maj | BM8: Skor | BN8: KPI | BO8: TO Low Min Low | BP8: Skor | BQ8: KPI | BR8: Visit | BS8: Skor | BT8: KPI | BU8: KPI 4.1 | BV8: KPI 4.2 | BW8: KPI 5.1 | BX8: KPI 5.2
S9: Crit | T9: Maj | U9: Min | V9: Low | W9: Crit | X9: Maj | Y9: Min | Z9: Low | AA9: Crit | AB9: Maj | AC9: Min | AD9: Low | AW9: Crit | AX9: Maj | AY9: Min | AZ9: Low | BA9: Very Low | BB9: Crit | BC9: Maj | BD9: Min | BE9: Low | BF9: Very Low | BG9: Crit | BH9: Maj | BI9: Min | BJ9: Low | BK9: Very Low
A10: R01_Sumbagut | B10: NOP ACEH | C10: =RANK(D10,$D$10:$D$43,0) | D10: =(G10*0.35)+(O10*65%) | E10: =IF(D10>=0.95,"Istimewa",IF(D10>0.9,"Baik Sekali",IF(D10>0.85,"Baik",IF(D10>0.8,"Cukup","Kurang")))) | F10: =0.29*0.65 | G10: =N10 | H10: =VLOOKUP(B10,'KPI Availability'!B:O,14,) | I10: =VLOOKUP(B10,'KPI Availability'!B:P,15,) | J10: =VLOOKUP(B10,'KPI Availability'!B:Q,16,) | K10: =VLOOKUP(B10,'KPI Availability'!B:R,17,) | L10: =VLOOKUP(B10,'KPI Availability'!B:S,18,) | M10: =VLOOKUP(B10,'KPI Availability'!B:T,19,) | N10: =SUM(H10:M10) | O10: =P10+Q10+R10 | P10: =SUM(AA10:AD10,AG10,AJ10,AM10,AP10,AS10,AV10) | Q10: =SUM(BG10:BK10,BN10,BQ10,BT10) | R10: =SUM(BU10:BX10) | S10: =VLOOKUP(B10,'KPI Ticketing'!B:C,2,) | T10: =VLOOKUP(B10,'KPI Ticketing'!B:D,3,) | U10: =VLOOKUP(B10,'KPI Ticketing'!B:E,4,) | V10: =VLOOKUP(B10,'KPI Ticketing'!B:F,5,) | W10: =IF(S10<=4,100%,IF(S10<=6,70%,IF(S10<=8,40%,10%))) | X10: =IF(T10<=8,100%,IF(T10<=12,50%,25%)) | Y10: =IF(U10<=10,100%,IF(U10<=15,50%,25%)) | Z10: =IF(V10<=13,100%,IF(V10<=19,50%,25%)) | AA10: =W10*0.13 | AB10: =X10*0.06 | AC10: =Y10*0.04 | AD10: =Z10*0.02 | AE10: =VLOOKUP(B10,'KPI Ticketing'!B:N,13,) | AF10: =IF(AE10>=0.8,1,IF(AE10>=0.7,0.9,IF(AE10>=0.6,0.8,IF(AE10>=0.5,0.7,IF(AE10>=0.4,0.6,IF(AE10>=0.3,0.5,IF(AE10>=0.2,0.4,IF(AE10>=0.1,0.3,0.2)))))))) | AG10: =AF10*0.03 | AH10: =VLOOKUP(B10,'KPI Ticketing'!B:R,17,) | AI10: =IF(AH10>=0.8,1,IF(AH10>=0.7,0.9,IF(AH10>=0.6,0.8,IF(AH10>=0.5,0.7,IF(AH10>=0.4,0.6,IF(AH10>=0.3,0.5,IF(AH10>=0.2,0.4,IF(AH10>=0.1,0.3,0.2)))))))) | AJ10: =AI10*0.02 | AK10: =VLOOKUP(B10,'KPI Ticketing'!B:V,21,) | AL10: =IF(AK10>=0.9,1,IF(AK10>=0.8,0.9,IF(AK10>=0.7,0.8,IF(AK10>=0.6,0.7,IF(AK10>=0.5,0.6,IF(AK10>=0.4,0.5,IF(AK10>=0.3,0.4,IF(AK10>=0.2,0.3,IF(AK10>=0.1,0.2,0.1))))))))) | AM10: =AL10*0.05 | AN10: =VLOOKUP(B10,'KPI Ticketing'!B:Z,25,) | AO10: =IF(AN10>=0.95,1,IF(AN10>=0.9,0.9,IF(AN10>=0.8,0.8,IF(AN10>=0.7,0.7,IF(AN10>=0.6,0.6,IF(AN10>=0.5,0.5,IF(AN10>=0.4,0.4,IF(AN10>=0.3,0.3,IF(AN10>=0.2,0.2,IF(AN10>=0.1,0.1,0.05)))))))))) | AP10: =AO10*0.05 | AQ10: =VLOOKUP(B10,'KPI Ticketing'!B:AC,28,) | AR10: =IF(AQ10<0.95,0.5,1) | AS10: =AR10*0.01 | AT10: =VLOOKUP(B10,'KPI Ticketing'!B:AG,32,) | AU10: =IF(AT10<0.3,0.5,1) | AV10: =AU10*0.01 | AW10: =VLOOKUP(B10,'KPI Ticketing'!B:AH,33,) | AX10: =VLOOKUP(B10,'KPI Ticketing'!B:AI,34,) | AY10: =VLOOKUP(B10,'KPI Ticketing'!B:AJ,35,) | AZ10: =VLOOKUP(B10,'KPI Ticketing'!B:AK,36,) | BA10: =VLOOKUP(B10,'KPI Ticketing'!B:AL,37,) | BB10: =IF(AW10<=2,1,IF(AW10<=3,0.7,IF(AW10<=4,0.4,0.1))) | BC10: =IF(AX10<=4,1,IF(AX10<=6,0.5,0.25)) | BD10: =IF(AY10<=15,1,IF(AY10<=22.5,0.5,0.25)) | BE10: =IF(AZ10<=48,1,IF(AZ10<=72,0.5,0.25)) | BF10: =IF(BA10=0, 0, IF(BA10<=96, 1, IF(BA10<=144, 0.5, 0.25))) | BG10: =BB10*0.1 | BH10: =BC10*0.05 | BI10: =BD10*0.02 | BJ10: =BE10*0.01 | BK10: =BF10*0.01 | BL10: =VLOOKUP(B10,'KPI Ticketing'!B:AT,45,) | BM10: =IF(BL10>=0.8,1,IF(BL10>=0.7,0.9,IF(BL10>=0.6,0.8,IF(BL10>=0.5,0.7,IF(BL10>=0.4,0.6,IF(BL10>=0.3,0.5,IF(BL10>=0.2,0.4,IF(BL10>=0.1,0.3,0.2)))))))) | BN10: =BM10*0.03 | BO10: =VLOOKUP(B10,'KPI Ticketing'!B:AX,49,) | BP10: =IF(BO10>=0.8,1,IF(BO10>=0.7,0.9,IF(BO10>=0.6,0.8,IF(BO10>=0.5,0.7,IF(BO10>=0.4,0.6,IF(BO10>=0.3,0.5,IF(BO10>=0.2,0.4,IF(BO10>=0.1,0.3,0.2)))))))) | BQ10: =BP10*0.02 | BR10: =VLOOKUP(B10,'KPI Ticketing'!B:BB,53,) | BS10: =IF(BR10>=0.9,1,IF(BR10>=0.8,0.9,IF(BR10>=0.7,0.8,IF(BR10>=0.6,0.7,IF(BR10>=0.5,0.6,IF(BR10>=0.4,0.5,IF(BR10>=0.3,0.4,IF(BR10>=0.2,0.3,IF(BR10>=0.1,0.2,0.1))))))))) | BT10: =BS10*0.05 | BU10: 0.08 | BV10: 0.06 | BW10: 0.09 | BX10: 0.06
A11: R01_Sumbagut | B11: NOP BINJAI | C11: =RANK(D11,$D$10:$D$43,0) | D11: =(G11*0.35)+(O11*65%) | E11: =IF(D11>=0.95,"Istimewa",IF(D11>0.9,"Baik Sekali",IF(D11>0.85,"Baik",IF(D11>0.8,"Cukup","Kurang")))) | F11: =0.29*0.65 | G11: =N11 | H11: =VLOOKUP(B11,'KPI Availability'!B:O,14,) | I11: =VLOOKUP(B11,'KPI Availability'!B:P,15,) | J11: =VLOOKUP(B11,'KPI Availability'!B:Q,16,) | K11: =VLOOKUP(B11,'KPI Availability'!B:R,17,) | L11: =VLOOKUP(B11,'KPI Availability'!B:S,18,) | M11: =VLOOKUP(B11,'KPI Availability'!B:T,19,) | N11: =SUM(H11:M11) | O11: =P11+Q11+R11 | P11: =SUM(AA11:AD11,AG11,AJ11,AM11,AP11,AS11,AV11) | Q11: =SUM(BG11:BK11,BN11,BQ11,BT11) | R11: =SUM(BU11:BX11) | S11: =VLOOKUP(B11,'KPI Ticketing'!B:C,2,) | T11: =VLOOKUP(B11,'KPI Ticketing'!B:D,3,) | U11: =VLOOKUP(B11,'KPI Ticketing'!B:E,4,) | V11: =VLOOKUP(B11,'KPI Ticketing'!B:F,5,) | W11: =IF(S11<=4,100%,IF(S11<=6,70%,IF(S11<=8,40%,10%))) | X11: =IF(T11<=8,100%,IF(T11<=12,50%,25%)) | Y11: =IF(U11<=10,100%,IF(U11<=15,50%,25%)) | Z11: =IF(V11<=13,100%,IF(V11<=19,50%,25%)) | AA11: =W11*0.13 | AB11: =X11*0.06 | AC11: =Y11*0.04 | AD11: =Z11*0.02 | AE11: =VLOOKUP(B11,'KPI Ticketing'!B:N,13,) | AF11: =IF(AE11>=0.8,1,IF(AE11>=0.7,0.9,IF(AE11>=0.6,0.8,IF(AE11>=0.5,0.7,IF(AE11>=0.4,0.6,IF(AE11>=0.3,0.5,IF(AE11>=0.2,0.4,IF(AE11>=0.1,0.3,0.2)))))))) | AG11: =AF11*0.03 | AH11: =VLOOKUP(B11,'KPI Ticketing'!B:R,17,) | AI11: =IF(AH11>=0.8,1,IF(AH11>=0.7,0.9,IF(AH11>=0.6,0.8,IF(AH11>=0.5,0.7,IF(AH11>=0.4,0.6,IF(AH11>=0.3,0.5,IF(AH11>=0.2,0.4,IF(AH11>=0.1,0.3,0.2)))))))) | AJ11: =AI11*0.02 | AK11: =VLOOKUP(B11,'KPI Ticketing'!B:V,21,) | AL11: =IF(AK11>=0.9,1,IF(AK11>=0.8,0.9,IF(AK11>=0.7,0.8,IF(AK11>=0.6,0.7,IF(AK11>=0.5,0.6,IF(AK11>=0.4,0.5,IF(AK11>=0.3,0.4,IF(AK11>=0.2,0.3,IF(AK11>=0.1,0.2,0.1))))))))) | AM11: =AL11*0.05 | AN11: =VLOOKUP(B11,'KPI Ticketing'!B:Z,25,) | AO11: =IF(AN11>=0.95,1,IF(AN11>=0.9,0.9,IF(AN11>=0.8,0.8,IF(AN11>=0.7,0.7,IF(AN11>=0.6,0.6,IF(AN11>=0.5,0.5,IF(AN11>=0.4,0.4,IF(AN11>=0.3,0.3,IF(AN11>=0.2,0.2,IF(AN11>=0.1,0.1,0.05)))))))))) | AP11: =AO11*0.05 | AQ11: =VLOOKUP(B11,'KPI Ticketing'!B:AC,28,) | AR11: =IF(AQ11<0.95,0.5,1) | AS11: =AR11*0.01 | AT11: =VLOOKUP(B11,'KPI Ticketing'!B:AG,32,) | AU11: =IF(AT11<0.3,0.5,1) | AV11: =AU11*0.01 | AW11: =VLOOKUP(B11,'KPI Ticketing'!B:AH,33,) | AX11: =VLOOKUP(B11,'KPI Ticketing'!B:AI,34,) | AY11: =VLOOKUP(B11,'KPI Ticketing'!B:AJ,35,) | AZ11: =VLOOKUP(B11,'KPI Ticketing'!B:AK,36,) | BA11: =VLOOKUP(B11,'KPI Ticketing'!B:AL,37,) | BB11: =IF(AW11<=2,1,IF(AW11<=3,0.7,IF(AW11<=4,0.4,0.1))) | BC11: =IF(AX11<=4,1,IF(AX11<=6,0.5,0.25)) | BD11: =IF(AY11<=15,1,IF(AY11<=22.5,0.5,0.25)) | BE11: =IF(AZ11<=48,1,IF(AZ11<=72,0.5,0.25)) | BF11: =IF(BA11=0, 0, IF(BA11<=96, 1, IF(BA11<=144, 0.5, 0.25))) | BG11: =BB11*0.1 | BH11: =BC11*0.05 | BI11: =BD11*0.02 | BJ11: =BE11*0.01 | BK11: =BF11*0.01 | BL11: =VLOOKUP(B11,'KPI Ticketing'!B:AT,45,) | BM11: =IF(BL11>=0.8,1,IF(BL11>=0.7,0.9,IF(BL11>=0.6,0.8,IF(BL11>=0.5,0.7,IF(BL11>=0.4,0.6,IF(BL11>=0.3,0.5,IF(BL11>=0.2,0.4,IF(BL11>=0.1,0.3,0.2)))))))) | BN11: =BM11*0.03 | BO11: =VLOOKUP(B11,'KPI Ticketing'!B:AX,49,) | BP11: =IF(BO11>=0.8,1,IF(BO11>=0.7,0.9,IF(BO11>=0.6,0.8,IF(BO11>=0.5,0.7,IF(BO11>=0.4,0.6,IF(BO11>=0.3,0.5,IF(BO11>=0.2,0.4,IF(BO11>=0.1,0.3,0.2)))))))) | BQ11: =BP11*0.02 | BR11: =VLOOKUP(B11,'KPI Ticketing'!B:BB,53,) | BS11: =IF(BR11>=0.9,1,IF(BR11>=0.8,0.9,IF(BR11>=0.7,0.8,IF(BR11>=0.6,0.7,IF(BR11>=0.5,0.6,IF(BR11>=0.4,0.5,IF(BR11>=0.3,0.4,IF(BR11>=0.2,0.3,IF(BR11>=0.1,0.2,0.1))))))))) | BT11: =BS11*0.05 | BU11: 0.08 | BV11: 0.06 | BW11: 0.09 | BX11: 0.06
A12: R01_Sumbagut | B12: NOP MEDAN | C12: =RANK(D12,$D$10:$D$43,0) | D12: =(G12*0.35)+(O12*65%) | E12: =IF(D12>=0.95,"Istimewa",IF(D12>0.9,"Baik Sekali",IF(D12>0.85,"Baik",IF(D12>0.8,"Cukup","Kurang")))) | F12: =0.29*0.65 | G12: =N12 | H12: =VLOOKUP(B12,'KPI Availability'!B:O,14,) | I12: =VLOOKUP(B12,'KPI Availability'!B:P,15,) | J12: =VLOOKUP(B12,'KPI Availability'!B:Q,16,) | K12: =VLOOKUP(B12,'KPI Availability'!B:R,17,) | L12: =VLOOKUP(B12,'KPI Availability'!B:S,18,) | M12: =VLOOKUP(B12,'KPI Availability'!B:T,19,) | N12: =SUM(H12:M12) | O12: =P12+Q12+R12 | P12: =SUM(AA12:AD12,AG12,AJ12,AM12,AP12,AS12,AV12) | Q12: =SUM(BG12:BK12,BN12,BQ12,BT12) | R12: =SUM(BU12:BX12) | S12: =VLOOKUP(B12,'KPI Ticketing'!B:C,2,) | T12: =VLOOKUP(B12,'KPI Ticketing'!B:D,3,) | U12: =VLOOKUP(B12,'KPI Ticketing'!B:E,4,) | V12: =VLOOKUP(B12,'KPI Ticketing'!B:F,5,) | W12: =IF(S12<=4,100%,IF(S12<=6,70%,IF(S12<=8,40%,10%))) | X12: =IF(T12<=8,100%,IF(T12<=12,50%,25%)) | Y12: =IF(U12<=10,100%,IF(U12<=15,50%,25%)) | Z12: =IF(V12<=13,100%,IF(V12<=19,50%,25%)) | AA12: =W12*0.13 | AB12: =X12*0.06 | AC12: =Y12*0.04 | AD12: =Z12*0.02 | AE12: =VLOOKUP(B12,'KPI Ticketing'!B:N,13,) | AF12: =IF(AE12>=0.8,1,IF(AE12>=0.7,0.9,IF(AE12>=0.6,0.8,IF(AE12>=0.5,0.7,IF(AE12>=0.4,0.6,IF(AE12>=0.3,0.5,IF(AE12>=0.2,0.4,IF(AE12>=0.1,0.3,0.2)))))))) | AG12: =AF12*0.03 | AH12: =VLOOKUP(B12,'KPI Ticketing'!B:R,17,) | AI12: =IF(AH12>=0.8,1,IF(AH12>=0.7,0.9,IF(AH12>=0.6,0.8,IF(AH12>=0.5,0.7,IF(AH12>=0.4,0.6,IF(AH12>=0.3,0.5,IF(AH12>=0.2,0.4,IF(AH12>=0.1,0.3,0.2)))))))) | AJ12: =AI12*0.02 | AK12: =VLOOKUP(B12,'KPI Ticketing'!B:V,21,) | AL12: =IF(AK12>=0.9,1,IF(AK12>=0.8,0.9,IF(AK12>=0.7,0.8,IF(AK12>=0.6,0.7,IF(AK12>=0.5,0.6,IF(AK12>=0.4,0.5,IF(AK12>=0.3,0.4,IF(AK12>=0.2,0.3,IF(AK12>=0.1,0.2,0.1))))))))) | AM12: =AL12*0.05 | AN12: =VLOOKUP(B12,'KPI Ticketing'!B:Z,25,) | AO12: =IF(AN12>=0.95,1,IF(AN12>=0.9,0.9,IF(AN12>=0.8,0.8,IF(AN12>=0.7,0.7,IF(AN12>=0.6,0.6,IF(AN12>=0.5,0.5,IF(AN12>=0.4,0.4,IF(AN12>=0.3,0.3,IF(AN12>=0.2,0.2,IF(AN12>=0.1,0.1,0.05)))))))))) | AP12: =AO12*0.05 | AQ12: =VLOOKUP(B12,'KPI Ticketing'!B:AC,28,) | AR12: =IF(AQ12<0.95,0.5,1) | AS12: =AR12*0.01 | AT12: =VLOOKUP(B12,'KPI Ticketing'!B:AG,32,) | AU12: =IF(AT12<0.3,0.5,1) | AV12: =AU12*0.01 | AW12: =VLOOKUP(B12,'KPI Ticketing'!B:AH,33,) | AX12: =VLOOKUP(B12,'KPI Ticketing'!B:AI,34,) | AY12: =VLOOKUP(B12,'KPI Ticketing'!B:AJ,35,) | AZ12: =VLOOKUP(B12,'KPI Ticketing'!B:AK,36,) | BA12: =VLOOKUP(B12,'KPI Ticketing'!B:AL,37,) | BB12: =IF(AW12<=2,1,IF(AW12<=3,0.7,IF(AW12<=4,0.4,0.1))) | BC12: =IF(AX12<=4,1,IF(AX12<=6,0.5,0.25)) | BD12: =IF(AY12<=15,1,IF(AY12<=22.5,0.5,0.25)) | BE12: =IF(AZ12<=48,1,IF(AZ12<=72,0.5,0.25)) | BF12: =IF(BA12=0, 0, IF(BA12<=96, 1, IF(BA12<=144, 0.5, 0.25))) | BG12: =BB12*0.1 | BH12: =BC12*0.05 | BI12: =BD12*0.02 | BJ12: =BE12*0.01 | BK12: =BF12*0.01 | BL12: =VLOOKUP(B12,'KPI Ticketing'!B:AT,45,) | BM12: =IF(BL12>=0.8,1,IF(BL12>=0.7,0.9,IF(BL12>=0.6,0.8,IF(BL12>=0.5,0.7,IF(BL12>=0.4,0.6,IF(BL12>=0.3,0.5,IF(BL12>=0.2,0.4,IF(BL12>=0.1,0.3,0.2)))))))) | BN12: =BM12*0.03 | BO12: =VLOOKUP(B12,'KPI Ticketing'!B:AX,49,) | BP12: =IF(BO12>=0.8,1,IF(BO12>=0.7,0.9,IF(BO12>=0.6,0.8,IF(BO12>=0.5,0.7,IF(BO12>=0.4,0.6,IF(BO12>=0.3,0.5,IF(BO12>=0.2,0.4,IF(BO12>=0.1,0.3,0.2)))))))) | BQ12: =BP12*0.02 | BR12: =VLOOKUP(B12,'KPI Ticketing'!B:BB,53,) | BS12: =IF(BR12>=0.9,1,IF(BR12>=0.8,0.9,IF(BR12>=0.7,0.8,IF(BR12>=0.6,0.7,IF(BR12>=0.5,0.6,IF(BR12>=0.4,0.5,IF(BR12>=0.3,0.4,IF(BR12>=0.2,0.3,IF(BR12>=0.1,0.2,0.1))))))))) | BT12: =BS12*0.05 | BU12: 0.08 | BV12: 0.06 | BW12: 0.09 | BX12: 0.06
A13: R01_Sumbagut | B13: NOP PADANG SIDEMPUAN | C13: =RANK(D13,$D$10:$D$43,0) | D13: =(G13*0.35)+(O13*65%) | E13: =IF(D13>=0.95,"Istimewa",IF(D13>0.9,"Baik Sekali",IF(D13>0.85,"Baik",IF(D13>0.8,"Cukup","Kurang")))) | F13: =0.29*0.65 | G13: =N13 | H13: =VLOOKUP(B13,'KPI Availability'!B:O,14,) | I13: =VLOOKUP(B13,'KPI Availability'!B:P,15,) | J13: =VLOOKUP(B13,'KPI Availability'!B:Q,16,) | K13: =VLOOKUP(B13,'KPI Availability'!B:R,17,) | L13: =VLOOKUP(B13,'KPI Availability'!B:S,18,) | M13: =VLOOKUP(B13,'KPI Availability'!B:T,19,) | N13: =SUM(H13:M13) | O13: =P13+Q13+R13 | P13: =SUM(AA13:AD13,AG13,AJ13,AM13,AP13,AS13,AV13) | Q13: =SUM(BG13:BK13,BN13,BQ13,BT13) | R13: =SUM(BU13:BX13) | S13: =VLOOKUP(B13,'KPI Ticketing'!B:C,2,) | T13: =VLOOKUP(B13,'KPI Ticketing'!B:D,3,) | U13: =VLOOKUP(B13,'KPI Ticketing'!B:E,4,) | V13: =VLOOKUP(B13,'KPI Ticketing'!B:F,5,) | W13: =IF(S13<=4,100%,IF(S13<=6,70%,IF(S13<=8,40%,10%))) | X13: =IF(T13<=8,100%,IF(T13<=12,50%,25%)) | Y13: =IF(U13<=10,100%,IF(U13<=15,50%,25%)) | Z13: =IF(V13<=13,100%,IF(V13<=19,50%,25%)) | AA13: =W13*0.13 | AB13: =X13*0.06 | AC13: =Y13*0.04 | AD13: =Z13*0.02 | AE13: =VLOOKUP(B13,'KPI Ticketing'!B:N,13,) | AF13: =IF(AE13>=0.8,1,IF(AE13>=0.7,0.9,IF(AE13>=0.6,0.8,IF(AE13>=0.5,0.7,IF(AE13>=0.4,0.6,IF(AE13>=0.3,0.5,IF(AE13>=0.2,0.4,IF(AE13>=0.1,0.3,0.2)))))))) | AG13: =AF13*0.03 | AH13: =VLOOKUP(B13,'KPI Ticketing'!B:R,17,) | AI13: =IF(AH13>=0.8,1,IF(AH13>=0.7,0.9,IF(AH13>=0.6,0.8,IF(AH13>=0.5,0.7,IF(AH13>=0.4,0.6,IF(AH13>=0.3,0.5,IF(AH13>=0.2,0.4,IF(AH13>=0.1,0.3,0.2)))))))) | AJ13: =AI13*0.02 | AK13: =VLOOKUP(B13,'KPI Ticketing'!B:V,21,) | AL13: =IF(AK13>=0.9,1,IF(AK13>=0.8,0.9,IF(AK13>=0.7,0.8,IF(AK13>=0.6,0.7,IF(AK13>=0.5,0.6,IF(AK13>=0.4,0.5,IF(AK13>=0.3,0.4,IF(AK13>=0.2,0.3,IF(AK13>=0.1,0.2,0.1))))))))) | AM13: =AL13*0.05 | AN13: =VLOOKUP(B13,'KPI Ticketing'!B:Z,25,) | AO13: =IF(AN13>=0.95,1,IF(AN13>=0.9,0.9,IF(AN13>=0.8,0.8,IF(AN13>=0.7,0.7,IF(AN13>=0.6,0.6,IF(AN13>=0.5,0.5,IF(AN13>=0.4,0.4,IF(AN13>=0.3,0.3,IF(AN13>=0.2,0.2,IF(AN13>=0.1,0.1,0.05)))))))))) | AP13: =AO13*0.05 | AQ13: =VLOOKUP(B13,'KPI Ticketing'!B:AC,28,) | AR13: =IF(AQ13<0.95,0.5,1) | AS13: =AR13*0.01 | AT13: =VLOOKUP(B13,'KPI Ticketing'!B:AG,32,) | AU13: =IF(AT13<0.3,0.5,1) | AV13: =AU13*0.01 | AW13: =VLOOKUP(B13,'KPI Ticketing'!B:AH,33,) | AX13: =VLOOKUP(B13,'KPI Ticketing'!B:AI,34,) | AY13: =VLOOKUP(B13,'KPI Ticketing'!B:AJ,35,) | AZ13: =VLOOKUP(B13,'KPI Ticketing'!B:AK,36,) | BA13: =VLOOKUP(B13,'KPI Ticketing'!B:AL,37,) | BB13: =IF(AW13<=2,1,IF(AW13<=3,0.7,IF(AW13<=4,0.4,0.1))) | BC13: =IF(AX13<=4,1,IF(AX13<=6,0.5,0.25)) | BD13: =IF(AY13<=15,1,IF(AY13<=22.5,0.5,0.25)) | BE13: =IF(AZ13<=48,1,IF(AZ13<=72,0.5,0.25)) | BF13: =IF(BA13=0, 0, IF(BA13<=96, 1, IF(BA13<=144, 0.5, 0.25))) | BG13: =BB13*0.1 | BH13: =BC13*0.05 | BI13: =BD13*0.02 | BJ13: =BE13*0.01 | BK13: =BF13*0.01 | BL13: =VLOOKUP(B13,'KPI Ticketing'!B:AT,45,) | BM13: =IF(BL13>=0.8,1,IF(BL13>=0.7,0.9,IF(BL13>=0.6,0.8,IF(BL13>=0.5,0.7,IF(BL13>=0.4,0.6,IF(BL13>=0.3,0.5,IF(BL13>=0.2,0.4,IF(BL13>=0.1,0.3,0.2)))))))) | BN13: =BM13*0.03 | BO13: =VLOOKUP(B13,'KPI Ticketing'!B:AX,49,) | BP13: =IF(BO13>=0.8,1,IF(BO13>=0.7,0.9,IF(BO13>=0.6,0.8,IF(BO13>=0.5,0.7,IF(BO13>=0.4,0.6,IF(BO13>=0.3,0.5,IF(BO13>=0.2,0.4,IF(BO13>=0.1,0.3,0.2)))))))) | BQ13: =BP13*0.02 | BR13: =VLOOKUP(B13,'KPI Ticketing'!B:BB,53,) | BS13: =IF(BR13>=0.9,1,IF(BR13>=0.8,0.9,IF(BR13>=0.7,0.8,IF(BR13>=0.6,0.7,IF(BR13>=0.5,0.6,IF(BR13>=0.4,0.5,IF(BR13>=0.3,0.4,IF(BR13>=0.2,0.3,IF(BR13>=0.1,0.2,0.1))))))))) | BT13: =BS13*0.05 | BU13: 0.08 | BV13: 0.06 | BW13: 0.09 | BX13: 0.06
A14: R01_Sumbagut | B14: NOP PEMATANG SIANTAR | C14: =RANK(D14,$D$10:$D$43,0) | D14: =(G14*0.35)+(O14*65%) | E14: =IF(D14>=0.95,"Istimewa",IF(D14>0.9,"Baik Sekali",IF(D14>0.85,"Baik",IF(D14>0.8,"Cukup","Kurang")))) | F14: =0.29*0.65 | G14: =N14 | H14: =VLOOKUP(B14,'KPI Availability'!B:O,14,) | I14: =VLOOKUP(B14,'KPI Availability'!B:P,15,) | J14: =VLOOKUP(B14,'KPI Availability'!B:Q,16,) | K14: =VLOOKUP(B14,'KPI Availability'!B:R,17,) | L14: =VLOOKUP(B14,'KPI Availability'!B:S,18,) | M14: =VLOOKUP(B14,'KPI Availability'!B:T,19,) | N14: =SUM(H14:M14) | O14: =P14+Q14+R14 | P14: =SUM(AA14:AD14,AG14,AJ14,AM14,AP14,AS14,AV14) | Q14: =SUM(BG14:BK14,BN14,BQ14,BT14) | R14: =SUM(BU14:BX14) | S14: =VLOOKUP(B14,'KPI Ticketing'!B:C,2,) | T14: =VLOOKUP(B14,'KPI Ticketing'!B:D,3,) | U14: =VLOOKUP(B14,'KPI Ticketing'!B:E,4,) | V14: =VLOOKUP(B14,'KPI Ticketing'!B:F,5,) | W14: =IF(S14<=4,100%,IF(S14<=6,70%,IF(S14<=8,40%,10%))) | X14: =IF(T14<=8,100%,IF(T14<=12,50%,25%)) | Y14: =IF(U14<=10,100%,IF(U14<=15,50%,25%)) | Z14: =IF(V14<=13,100%,IF(V14<=19,50%,25%)) | AA14: =W14*0.13 | AB14: =X14*0.06 | AC14: =Y14*0.04 | AD14: =Z14*0.02 | AE14: =VLOOKUP(B14,'KPI Ticketing'!B:N,13,) | AF14: =IF(AE14>=0.8,1,IF(AE14>=0.7,0.9,IF(AE14>=0.6,0.8,IF(AE14>=0.5,0.7,IF(AE14>=0.4,0.6,IF(AE14>=0.3,0.5,IF(AE14>=0.2,0.4,IF(AE14>=0.1,0.3,0.2)))))))) | AG14: =AF14*0.03 | AH14: =VLOOKUP(B14,'KPI Ticketing'!B:R,17,) | AI14: =IF(AH14>=0.8,1,IF(AH14>=0.7,0.9,IF(AH14>=0.6,0.8,IF(AH14>=0.5,0.7,IF(AH14>=0.4,0.6,IF(AH14>=0.3,0.5,IF(AH14>=0.2,0.4,IF(AH14>=0.1,0.3,0.2)))))))) | AJ14: =AI14*0.02 | AK14: =VLOOKUP(B14,'KPI Ticketing'!B:V,21,) | AL14: =IF(AK14>=0.9,1,IF(AK14>=0.8,0.9,IF(AK14>=0.7,0.8,IF(AK14>=0.6,0.7,IF(AK14>=0.5,0.6,IF(AK14>=0.4,0.5,IF(AK14>=0.3,0.4,IF(AK14>=0.2,0.3,IF(AK14>=0.1,0.2,0.1))))))))) | AM14: =AL14*0.05 | AN14: =VLOOKUP(B14,'KPI Ticketing'!B:Z,25,) | AO14: =IF(AN14>=0.95,1,IF(AN14>=0.9,0.9,IF(AN14>=0.8,0.8,IF(AN14>=0.7,0.7,IF(AN14>=0.6,0.6,IF(AN14>=0.5,0.5,IF(AN14>=0.4,0.4,IF(AN14>=0.3,0.3,IF(AN14>=0.2,0.2,IF(AN14>=0.1,0.1,0.05)))))))))) | AP14: =AO14*0.05 | AQ14: =VLOOKUP(B14,'KPI Ticketing'!B:AC,28,) | AR14: =IF(AQ14<0.95,0.5,1) | AS14: =AR14*0.01 | AT14: =VLOOKUP(B14,'KPI Ticketing'!B:AG,32,) | AU14: =IF(AT14<0.3,0.5,1) | AV14: =AU14*0.01 | AW14: =VLOOKUP(B14,'KPI Ticketing'!B:AH,33,) | AX14: =VLOOKUP(B14,'KPI Ticketing'!B:AI,34,) | AY14: =VLOOKUP(B14,'KPI Ticketing'!B:AJ,35,) | AZ14: =VLOOKUP(B14,'KPI Ticketing'!B:AK,36,) | BA14: =VLOOKUP(B14,'KPI Ticketing'!B:AL,37,) | BB14: =IF(AW14<=2,1,IF(AW14<=3,0.7,IF(AW14<=4,0.4,0.1))) | BC14: =IF(AX14<=4,1,IF(AX14<=6,0.5,0.25)) | BD14: =IF(AY14<=15,1,IF(AY14<=22.5,0.5,0.25)) | BE14: =IF(AZ14<=48,1,IF(AZ14<=72,0.5,0.25)) | BF14: =IF(BA14=0, 0, IF(BA14<=96, 1, IF(BA14<=144, 0.5, 0.25))) | BG14: =BB14*0.1 | BH14: =BC14*0.05 | BI14: =BD14*0.02 | BJ14: =BE14*0.01 | BK14: =BF14*0.01 | BL14: =VLOOKUP(B14,'KPI Ticketing'!B:AT,45,) | BM14: =IF(BL14>=0.8,1,IF(BL14>=0.7,0.9,IF(BL14>=0.6,0.8,IF(BL14>=0.5,0.7,IF(BL14>=0.4,0.6,IF(BL14>=0.3,0.5,IF(BL14>=0.2,0.4,IF(BL14>=0.1,0.3,0.2)))))))) | BN14: =BM14*0.03 | BO14: =VLOOKUP(B14,'KPI Ticketing'!B:AX,49,) | BP14: =IF(BO14>=0.8,1,IF(BO14>=0.7,0.9,IF(BO14>=0.6,0.8,IF(BO14>=0.5,0.7,IF(BO14>=0.4,0.6,IF(BO14>=0.3,0.5,IF(BO14>=0.2,0.4,IF(BO14>=0.1,0.3,0.2)))))))) | BQ14: =BP14*0.02 | BR14: =VLOOKUP(B14,'KPI Ticketing'!B:BB,53,) | BS14: =IF(BR14>=0.9,1,IF(BR14>=0.8,0.9,IF(BR14>=0.7,0.8,IF(BR14>=0.6,0.7,IF(BR14>=0.5,0.6,IF(BR14>=0.4,0.5,IF(BR14>=0.3,0.4,IF(BR14>=0.2,0.3,IF(BR14>=0.1,0.2,0.1))))))))) | BT14: =BS14*0.05 | BU14: 0.08 | BV14: 0.06 | BW14: 0.09 | BX14: 0.06
A15: R01_Sumbagut | B15: NOP RANTAU PRAPAT | C15: =RANK(D15,$D$10:$D$43,0) | D15: =(G15*0.35)+(O15*65%) | E15: =IF(D15>=0.95,"Istimewa",IF(D15>0.9,"Baik Sekali",IF(D15>0.85,"Baik",IF(D15>0.8,"Cukup","Kurang")))) | F15: =0.29*0.65 | G15: =N15 | H15: =VLOOKUP(B15,'KPI Availability'!B:O,14,) | I15: =VLOOKUP(B15,'KPI Availability'!B:P,15,) | J15: =VLOOKUP(B15,'KPI Availability'!B:Q,16,) | K15: =VLOOKUP(B15,'KPI Availability'!B:R,17,) | L15: =VLOOKUP(B15,'KPI Availability'!B:S,18,) | M15: =VLOOKUP(B15,'KPI Availability'!B:T,19,) | N15: =SUM(H15:M15) | O15: =P15+Q15+R15 | P15: =SUM(AA15:AD15,AG15,AJ15,AM15,AP15,AS15,AV15) | Q15: =SUM(BG15:BK15,BN15,BQ15,BT15) | R15: =SUM(BU15:BX15) | S15: =VLOOKUP(B15,'KPI Ticketing'!B:C,2,) | T15: =VLOOKUP(B15,'KPI Ticketing'!B:D,3,) | U15: =VLOOKUP(B15,'KPI Ticketing'!B:E,4,) | V15: =VLOOKUP(B15,'KPI Ticketing'!B:F,5,) | W15: =IF(S15<=4,100%,IF(S15<=6,70%,IF(S15<=8,40%,10%))) | X15: =IF(T15<=8,100%,IF(T15<=12,50%,25%)) | Y15: =IF(U15<=10,100%,IF(U15<=15,50%,25%)) | Z15: =IF(V15<=13,100%,IF(V15<=19,50%,25%)) | AA15: =W15*0.13 | AB15: =X15*0.06 | AC15: =Y15*0.04 | AD15: =Z15*0.02 | AE15: =VLOOKUP(B15,'KPI Ticketing'!B:N,13,) | AF15: =IF(AE15>=0.8,1,IF(AE15>=0.7,0.9,IF(AE15>=0.6,0.8,IF(AE15>=0.5,0.7,IF(AE15>=0.4,0.6,IF(AE15>=0.3,0.5,IF(AE15>=0.2,0.4,IF(AE15>=0.1,0.3,0.2)))))))) | AG15: =AF15*0.03 | AH15: =VLOOKUP(B15,'KPI Ticketing'!B:R,17,) | AI15: =IF(AH15>=0.8,1,IF(AH15>=0.7,0.9,IF(AH15>=0.6,0.8,IF(AH15>=0.5,0.7,IF(AH15>=0.4,0.6,IF(AH15>=0.3,0.5,IF(AH15>=0.2,0.4,IF(AH15>=0.1,0.3,0.2)))))))) | AJ15: =AI15*0.02 | AK15: =VLOOKUP(B15,'KPI Ticketing'!B:V,21,) | AL15: =IF(AK15>=0.9,1,IF(AK15>=0.8,0.9,IF(AK15>=0.7,0.8,IF(AK15>=0.6,0.7,IF(AK15>=0.5,0.6,IF(AK15>=0.4,0.5,IF(AK15>=0.3,0.4,IF(AK15>=0.2,0.3,IF(AK15>=0.1,0.2,0.1))))))))) | AM15: =AL15*0.05 | AN15: =VLOOKUP(B15,'KPI Ticketing'!B:Z,25,) | AO15: =IF(AN15>=0.95,1,IF(AN15>=0.9,0.9,IF(AN15>=0.8,0.8,IF(AN15>=0.7,0.7,IF(AN15>=0.6,0.6,IF(AN15>=0.5,0.5,IF(AN15>=0.4,0.4,IF(AN15>=0.3,0.3,IF(AN15>=0.2,0.2,IF(AN15>=0.1,0.1,0.05)))))))))) | AP15: =AO15*0.05 | AQ15: =VLOOKUP(B15,'KPI Ticketing'!B:AC,28,) | AR15: =IF(AQ15<0.95,0.5,1) | AS15: =AR15*0.01 | AT15: =VLOOKUP(B15,'KPI Ticketing'!B:AG,32,) | AU15: =IF(AT15<0.3,0.5,1) | AV15: =AU15*0.01 | AW15: =VLOOKUP(B15,'KPI Ticketing'!B:AH,33,) | AX15: =VLOOKUP(B15,'KPI Ticketing'!B:AI,34,) | AY15: =VLOOKUP(B15,'KPI Ticketing'!B:AJ,35,) | AZ15: =VLOOKUP(B15,'KPI Ticketing'!B:AK,36,) | BA15: =VLOOKUP(B15,'KPI Ticketing'!B:AL,37,) | BB15: =IF(AW15<=2,1,IF(AW15<=3,0.7,IF(AW15<=4,0.4,0.1))) | BC15: =IF(AX15<=4,1,IF(AX15<=6,0.5,0.25)) | BD15: =IF(AY15<=15,1,IF(AY15<=22.5,0.5,0.25)) | BE15: =IF(AZ15<=48,1,IF(AZ15<=72,0.5,0.25)) | BF15: =IF(BA15=0, 0, IF(BA15<=96, 1, IF(BA15<=144, 0.5, 0.25))) | BG15: =BB15*0.1 | BH15: =BC15*0.05 | BI15: =BD15*0.02 | BJ15: =BE15*0.01 | BK15: =BF15*0.01 | BL15: =VLOOKUP(B15,'KPI Ticketing'!B:AT,45,) | BM15: =IF(BL15>=0.8,1,IF(BL15>=0.7,0.9,IF(BL15>=0.6,0.8,IF(BL15>=0.5,0.7,IF(BL15>=0.4,0.6,IF(BL15>=0.3,0.5,IF(BL15>=0.2,0.4,IF(BL15>=0.1,0.3,0.2)))))))) | BN15: =BM15*0.03 | BO15: =VLOOKUP(B15,'KPI Ticketing'!B:AX,49,) | BP15: =IF(BO15>=0.8,1,IF(BO15>=0.7,0.9,IF(BO15>=0.6,0.8,IF(BO15>=0.5,0.7,IF(BO15>=0.4,0.6,IF(BO15>=0.3,0.5,IF(BO15>=0.2,0.4,IF(BO15>=0.1,0.3,0.2)))))))) | BQ15: =BP15*0.02 | BR15: =VLOOKUP(B15,'KPI Ticketing'!B:BB,53,) | BS15: =IF(BR15>=0.9,1,IF(BR15>=0.8,0.9,IF(BR15>=0.7,0.8,IF(BR15>=0.6,0.7,IF(BR15>=0.5,0.6,IF(BR15>=0.4,0.5,IF(BR15>=0.3,0.4,IF(BR15>=0.2,0.3,IF(BR15>=0.1,0.2,0.1))))))))) | BT15: =BS15*0.05 | BU15: 0.08 | BV15: 0.06 | BW15: 0.09 | BX15: 0.06
A16: R10_Sumbagteng | B16: NOP BATAM | C16: =RANK(D16,$D$10:$D$43,0) | D16: =(G16*0.35)+(O16*65%) | E16: =IF(D16>=0.95,"Istimewa",IF(D16>0.9,"Baik Sekali",IF(D16>0.85,"Baik",IF(D16>0.8,"Cukup","Kurang")))) | F16: =0.29*0.65 | G16: =N16 | H16: =VLOOKUP(B16,'KPI Availability'!B:O,14,) | I16: =VLOOKUP(B16,'KPI Availability'!B:P,15,) | J16: =VLOOKUP(B16,'KPI Availability'!B:Q,16,) | K16: =VLOOKUP(B16,'KPI Availability'!B:R,17,) | L16: =VLOOKUP(B16,'KPI Availability'!B:S,18,) | M16: =VLOOKUP(B16,'KPI Availability'!B:T,19,) | N16: =SUM(H16:M16) | O16: =P16+Q16+R16 | P16: =SUM(AA16:AD16,AG16,AJ16,AM16,AP16,AS16,AV16) | Q16: =SUM(BG16:BK16,BN16,BQ16,BT16) | R16: =SUM(BU16:BX16) | S16: =VLOOKUP(B16,'KPI Ticketing'!B:C,2,) | T16: =VLOOKUP(B16,'KPI Ticketing'!B:D,3,) | U16: =VLOOKUP(B16,'KPI Ticketing'!B:E,4,) | V16: =VLOOKUP(B16,'KPI Ticketing'!B:F,5,) | W16: =IF(S16<=4,100%,IF(S16<=6,70%,IF(S16<=8,40%,10%))) | X16: =IF(T16<=8,100%,IF(T16<=12,50%,25%)) | Y16: =IF(U16<=10,100%,IF(U16<=15,50%,25%)) | Z16: =IF(V16<=13,100%,IF(V16<=19,50%,25%)) | AA16: =W16*0.13 | AB16: =X16*0.06 | AC16: =Y16*0.04 | AD16: =Z16*0.02 | AE16: =VLOOKUP(B16,'KPI Ticketing'!B:N,13,) | AF16: =IF(AE16>=0.8,1,IF(AE16>=0.7,0.9,IF(AE16>=0.6,0.8,IF(AE16>=0.5,0.7,IF(AE16>=0.4,0.6,IF(AE16>=0.3,0.5,IF(AE16>=0.2,0.4,IF(AE16>=0.1,0.3,0.2)))))))) | AG16: =AF16*0.03 | AH16: =VLOOKUP(B16,'KPI Ticketing'!B:R,17,) | AI16: =IF(AH16>=0.8,1,IF(AH16>=0.7,0.9,IF(AH16>=0.6,0.8,IF(AH16>=0.5,0.7,IF(AH16>=0.4,0.6,IF(AH16>=0.3,0.5,IF(AH16>=0.2,0.4,IF(AH16>=0.1,0.3,0.2)))))))) | AJ16: =AI16*0.02 | AK16: =VLOOKUP(B16,'KPI Ticketing'!B:V,21,) | AL16: =IF(AK16>=0.9,1,IF(AK16>=0.8,0.9,IF(AK16>=0.7,0.8,IF(AK16>=0.6,0.7,IF(AK16>=0.5,0.6,IF(AK16>=0.4,0.5,IF(AK16>=0.3,0.4,IF(AK16>=0.2,0.3,IF(AK16>=0.1,0.2,0.1))))))))) | AM16: =AL16*0.05 | AN16: =VLOOKUP(B16,'KPI Ticketing'!B:Z,25,) | AO16: =IF(AN16>=0.95,1,IF(AN16>=0.9,0.9,IF(AN16>=0.8,0.8,IF(AN16>=0.7,0.7,IF(AN16>=0.6,0.6,IF(AN16>=0.5,0.5,IF(AN16>=0.4,0.4,IF(AN16>=0.3,0.3,IF(AN16>=0.2,0.2,IF(AN16>=0.1,0.1,0.05)))))))))) | AP16: =AO16*0.05 | AQ16: =VLOOKUP(B16,'KPI Ticketing'!B:AC,28,) | AR16: =IF(AQ16<0.95,0.5,1) | AS16: =AR16*0.01 | AT16: =VLOOKUP(B16,'KPI Ticketing'!B:AG,32,) | AU16: =IF(AT16<0.3,0.5,1) | AV16: =AU16*0.01 | AW16: =VLOOKUP(B16,'KPI Ticketing'!B:AH,33,) | AX16: =VLOOKUP(B16,'KPI Ticketing'!B:AI,34,) | AY16: =VLOOKUP(B16,'KPI Ticketing'!B:AJ,35,) | AZ16: =VLOOKUP(B16,'KPI Ticketing'!B:AK,36,) | BA16: =VLOOKUP(B16,'KPI Ticketing'!B:AL,37,) | BB16: =IF(AW16<=2,1,IF(AW16<=3,0.7,IF(AW16<=4,0.4,0.1))) | BC16: =IF(AX16<=4,1,IF(AX16<=6,0.5,0.25)) | BD16: =IF(AY16<=15,1,IF(AY16<=22.5,0.5,0.25)) | BE16: =IF(AZ16<=48,1,IF(AZ16<=72,0.5,0.25)) | BF16: =IF(BA16=0, 0, IF(BA16<=96, 1, IF(BA16<=144, 0.5, 0.25))) | BG16: =BB16*0.1 | BH16: =BC16*0.05 | BI16: =BD16*0.02 | BJ16: =BE16*0.01 | BK16: =BF16*0.01 | BL16: =VLOOKUP(B16,'KPI Ticketing'!B:AT,45,) | BM16: =IF(BL16>=0.8,1,IF(BL16>=0.7,0.9,IF(BL16>=0.6,0.8,IF(BL16>=0.5,0.7,IF(BL16>=0.4,0.6,IF(BL16>=0.3,0.5,IF(BL16>=0.2,0.4,IF(BL16>=0.1,0.3,0.2)))))))) | BN16: =BM16*0.03 | BO16: =VLOOKUP(B16,'KPI Ticketing'!B:AX,49,) | BP16: =IF(BO16>=0.8,1,IF(BO16>=0.7,0.9,IF(BO16>=0.6,0.8,IF(BO16>=0.5,0.7,IF(BO16>=0.4,0.6,IF(BO16>=0.3,0.5,IF(BO16>=0.2,0.4,IF(BO16>=0.1,0.3,0.2)))))))) | BQ16: =BP16*0.02 | BR16: =VLOOKUP(B16,'KPI Ticketing'!B:BB,53,) | BS16: =IF(BR16>=0.9,1,IF(BR16>=0.8,0.9,IF(BR16>=0.7,0.8,IF(BR16>=0.6,0.7,IF(BR16>=0.5,0.6,IF(BR16>=0.4,0.5,IF(BR16>=0.3,0.4,IF(BR16>=0.2,0.3,IF(BR16>=0.1,0.2,0.1))))))))) | BT16: =BS16*0.05 | BU16: 0.08 | BV16: 0.06 | BW16: 0.09 | BX16: 0.06
A17: R10_Sumbagteng | B17: NOP BUKITTINGGI | C17: =RANK(D17,$D$10:$D$43,0) | D17: =(G17*0.35)+(O17*65%) | E17: =IF(D17>=0.95,"Istimewa",IF(D17>0.9,"Baik Sekali",IF(D17>0.85,"Baik",IF(D17>0.8,"Cukup","Kurang")))) | F17: =0.29*0.65 | G17: =N17 | H17: =VLOOKUP(B17,'KPI Availability'!B:O,14,) | I17: =VLOOKUP(B17,'KPI Availability'!B:P,15,) | J17: =VLOOKUP(B17,'KPI Availability'!B:Q,16,) | K17: =VLOOKUP(B17,'KPI Availability'!B:R,17,) | L17: =VLOOKUP(B17,'KPI Availability'!B:S,18,) | M17: =VLOOKUP(B17,'KPI Availability'!B:T,19,) | N17: =SUM(H17:M17) | O17: =P17+Q17+R17 | P17: =SUM(AA17:AD17,AG17,AJ17,AM17,AP17,AS17,AV17) | Q17: =SUM(BG17:BK17,BN17,BQ17,BT17) | R17: =SUM(BU17:BX17) | S17: =VLOOKUP(B17,'KPI Ticketing'!B:C,2,) | T17: =VLOOKUP(B17,'KPI Ticketing'!B:D,3,) | U17: =VLOOKUP(B17,'KPI Ticketing'!B:E,4,) | V17: =VLOOKUP(B17,'KPI Ticketing'!B:F,5,) | W17: =IF(S17<=4,100%,IF(S17<=6,70%,IF(S17<=8,40%,10%))) | X17: =IF(T17<=8,100%,IF(T17<=12,50%,25%)) | Y17: =IF(U17<=10,100%,IF(U17<=15,50%,25%)) | Z17: =IF(V17<=13,100%,IF(V17<=19,50%,25%)) | AA17: =W17*0.13 | AB17: =X17*0.06 | AC17: =Y17*0.04 | AD17: =Z17*0.02 | AE17: =VLOOKUP(B17,'KPI Ticketing'!B:N,13,) | AF17: =IF(AE17>=0.8,1,IF(AE17>=0.7,0.9,IF(AE17>=0.6,0.8,IF(AE17>=0.5,0.7,IF(AE17>=0.4,0.6,IF(AE17>=0.3,0.5,IF(AE17>=0.2,0.4,IF(AE17>=0.1,0.3,0.2)))))))) | AG17: =AF17*0.03 | AH17: =VLOOKUP(B17,'KPI Ticketing'!B:R,17,) | AI17: =IF(AH17>=0.8,1,IF(AH17>=0.7,0.9,IF(AH17>=0.6,0.8,IF(AH17>=0.5,0.7,IF(AH17>=0.4,0.6,IF(AH17>=0.3,0.5,IF(AH17>=0.2,0.4,IF(AH17>=0.1,0.3,0.2)))))))) | AJ17: =AI17*0.02 | AK17: =VLOOKUP(B17,'KPI Ticketing'!B:V,21,) | AL17: =IF(AK17>=0.9,1,IF(AK17>=0.8,0.9,IF(AK17>=0.7,0.8,IF(AK17>=0.6,0.7,IF(AK17>=0.5,0.6,IF(AK17>=0.4,0.5,IF(AK17>=0.3,0.4,IF(AK17>=0.2,0.3,IF(AK17>=0.1,0.2,0.1))))))))) | AM17: =AL17*0.05 | AN17: =VLOOKUP(B17,'KPI Ticketing'!B:Z,25,) | AO17: =IF(AN17>=0.95,1,IF(AN17>=0.9,0.9,IF(AN17>=0.8,0.8,IF(AN17>=0.7,0.7,IF(AN17>=0.6,0.6,IF(AN17>=0.5,0.5,IF(AN17>=0.4,0.4,IF(AN17>=0.3,0.3,IF(AN17>=0.2,0.2,IF(AN17>=0.1,0.1,0.05)))))))))) | AP17: =AO17*0.05 | AQ17: =VLOOKUP(B17,'KPI Ticketing'!B:AC,28,) | AR17: =IF(AQ17<0.95,0.5,1) | AS17: =AR17*0.01 | AT17: =VLOOKUP(B17,'KPI Ticketing'!B:AG,32,) | AU17: =IF(AT17<0.3,0.5,1) | AV17: =AU17*0.01 | AW17: =VLOOKUP(B17,'KPI Ticketing'!B:AH,33,) | AX17: =VLOOKUP(B17,'KPI Ticketing'!B:AI,34,) | AY17: =VLOOKUP(B17,'KPI Ticketing'!B:AJ,35,) | AZ17: =VLOOKUP(B17,'KPI Ticketing'!B:AK,36,) | BA17: =VLOOKUP(B17,'KPI Ticketing'!B:AL,37,) | BB17: =IF(AW17<=2,1,IF(AW17<=3,0.7,IF(AW17<=4,0.4,0.1))) | BC17: =IF(AX17<=4,1,IF(AX17<=6,0.5,0.25)) | BD17: =IF(AY17<=15,1,IF(AY17<=22.5,0.5,0.25)) | BE17: =IF(AZ17<=48,1,IF(AZ17<=72,0.5,0.25)) | BF17: =IF(BA17=0, 0, IF(BA17<=96, 1, IF(BA17<=144, 0.5, 0.25))) | BG17: =BB17*0.1 | BH17: =BC17*0.05 | BI17: =BD17*0.02 | BJ17: =BE17*0.01 | BK17: =BF17*0.01 | BL17: =VLOOKUP(B17,'KPI Ticketing'!B:AT,45,) | BM17: =IF(BL17>=0.8,1,IF(BL17>=0.7,0.9,IF(BL17>=0.6,0.8,IF(BL17>=0.5,0.7,IF(BL17>=0.4,0.6,IF(BL17>=0.3,0.5,IF(BL17>=0.2,0.4,IF(BL17>=0.1,0.3,0.2)))))))) | BN17: =BM17*0.03 | BO17: =VLOOKUP(B17,'KPI Ticketing'!B:AX,49,) | BP17: =IF(BO17>=0.8,1,IF(BO17>=0.7,0.9,IF(BO17>=0.6,0.8,IF(BO17>=0.5,0.7,IF(BO17>=0.4,0.6,IF(BO17>=0.3,0.5,IF(BO17>=0.2,0.4,IF(BO17>=0.1,0.3,0.2)))))))) | BQ17: =BP17*0.02 | BR17: =VLOOKUP(B17,'KPI Ticketing'!B:BB,53,) | BS17: =IF(BR17>=0.9,1,IF(BR17>=0.8,0.9,IF(BR17>=0.7,0.8,IF(BR17>=0.6,0.7,IF(BR17>=0.5,0.6,IF(BR17>=0.4,0.5,IF(BR17>=0.3,0.4,IF(BR17>=0.2,0.3,IF(BR17>=0.1,0.2,0.1))))))))) | BT17: =BS17*0.05 | BU17: 0.08 | BV17: 0.06 | BW17: 0.09 | BX17: 0.06
A18: R10_Sumbagteng | B18: NOP DUMAI | C18: =RANK(D18,$D$10:$D$43,0) | D18: =(G18*0.35)+(O18*65%) | E18: =IF(D18>=0.95,"Istimewa",IF(D18>0.9,"Baik Sekali",IF(D18>0.85,"Baik",IF(D18>0.8,"Cukup","Kurang")))) | F18: =0.29*0.65 | G18: =N18 | H18: =VLOOKUP(B18,'KPI Availability'!B:O,14,) | I18: =VLOOKUP(B18,'KPI Availability'!B:P,15,) | J18: =VLOOKUP(B18,'KPI Availability'!B:Q,16,) | K18: =VLOOKUP(B18,'KPI Availability'!B:R,17,) | L18: =VLOOKUP(B18,'KPI Availability'!B:S,18,) | M18: =VLOOKUP(B18,'KPI Availability'!B:T,19,) | N18: =SUM(H18:M18) | O18: =P18+Q18+R18 | P18: =SUM(AA18:AD18,AG18,AJ18,AM18,AP18,AS18,AV18) | Q18: =SUM(BG18:BK18,BN18,BQ18,BT18) | R18: =SUM(BU18:BX18) | S18: =VLOOKUP(B18,'KPI Ticketing'!B:C,2,) | T18: =VLOOKUP(B18,'KPI Ticketing'!B:D,3,) | U18: =VLOOKUP(B18,'KPI Ticketing'!B:E,4,) | V18: =VLOOKUP(B18,'KPI Ticketing'!B:F,5,) | W18: =IF(S18<=4,100%,IF(S18<=6,70%,IF(S18<=8,40%,10%))) | X18: =IF(T18<=8,100%,IF(T18<=12,50%,25%)) | Y18: =IF(U18<=10,100%,IF(U18<=15,50%,25%)) | Z18: =IF(V18<=13,100%,IF(V18<=19,50%,25%)) | AA18: =W18*0.13 | AB18: =X18*0.06 | AC18: =Y18*0.04 | AD18: =Z18*0.02 | AE18: =VLOOKUP(B18,'KPI Ticketing'!B:N,13,) | AF18: =IF(AE18>=0.8,1,IF(AE18>=0.7,0.9,IF(AE18>=0.6,0.8,IF(AE18>=0.5,0.7,IF(AE18>=0.4,0.6,IF(AE18>=0.3,0.5,IF(AE18>=0.2,0.4,IF(AE18>=0.1,0.3,0.2)))))))) | AG18: =AF18*0.03 | AH18: =VLOOKUP(B18,'KPI Ticketing'!B:R,17,) | AI18: =IF(AH18>=0.8,1,IF(AH18>=0.7,0.9,IF(AH18>=0.6,0.8,IF(AH18>=0.5,0.7,IF(AH18>=0.4,0.6,IF(AH18>=0.3,0.5,IF(AH18>=0.2,0.4,IF(AH18>=0.1,0.3,0.2)))))))) | AJ18: =AI18*0.02 | AK18: =VLOOKUP(B18,'KPI Ticketing'!B:V,21,) | AL18: =IF(AK18>=0.9,1,IF(AK18>=0.8,0.9,IF(AK18>=0.7,0.8,IF(AK18>=0.6,0.7,IF(AK18>=0.5,0.6,IF(AK18>=0.4,0.5,IF(AK18>=0.3,0.4,IF(AK18>=0.2,0.3,IF(AK18>=0.1,0.2,0.1))))))))) | AM18: =AL18*0.05 | AN18: =VLOOKUP(B18,'KPI Ticketing'!B:Z,25,) | AO18: =IF(AN18>=0.95,1,IF(AN18>=0.9,0.9,IF(AN18>=0.8,0.8,IF(AN18>=0.7,0.7,IF(AN18>=0.6,0.6,IF(AN18>=0.5,0.5,IF(AN18>=0.4,0.4,IF(AN18>=0.3,0.3,IF(AN18>=0.2,0.2,IF(AN18>=0.1,0.1,0.05)))))))))) | AP18: =AO18*0.05 | AQ18: =VLOOKUP(B18,'KPI Ticketing'!B:AC,28,) | AR18: =IF(AQ18<0.95,0.5,1) | AS18: =AR18*0.01 | AT18: =VLOOKUP(B18,'KPI Ticketing'!B:AG,32,) | AU18: =IF(AT18<0.3,0.5,1) | AV18: =AU18*0.01 | AW18: =VLOOKUP(B18,'KPI Ticketing'!B:AH,33,) | AX18: =VLOOKUP(B18,'KPI Ticketing'!B:AI,34,) | AY18: =VLOOKUP(B18,'KPI Ticketing'!B:AJ,35,) | AZ18: =VLOOKUP(B18,'KPI Ticketing'!B:AK,36,) | BA18: =VLOOKUP(B18,'KPI Ticketing'!B:AL,37,) | BB18: =IF(AW18<=2,1,IF(AW18<=3,0.7,IF(AW18<=4,0.4,0.1))) | BC18: =IF(AX18<=4,1,IF(AX18<=6,0.5,0.25)) | BD18: =IF(AY18<=15,1,IF(AY18<=22.5,0.5,0.25)) | BE18: =IF(AZ18<=48,1,IF(AZ18<=72,0.5,0.25)) | BF18: =IF(BA18=0, 0, IF(BA18<=96, 1, IF(BA18<=144, 0.5, 0.25))) | BG18: =BB18*0.1 | BH18: =BC18*0.05 | BI18: =BD18*0.02 | BJ18: =BE18*0.01 | BK18: =BF18*0.01 | BL18: =VLOOKUP(B18,'KPI Ticketing'!B:AT,45,) | BM18: =IF(BL18>=0.8,1,IF(BL18>=0.7,0.9,IF(BL18>=0.6,0.8,IF(BL18>=0.5,0.7,IF(BL18>=0.4,0.6,IF(BL18>=0.3,0.5,IF(BL18>=0.2,0.4,IF(BL18>=0.1,0.3,0.2)))))))) | BN18: =BM18*0.03 | BO18: =VLOOKUP(B18,'KPI Ticketing'!B:AX,49,) | BP18: =IF(BO18>=0.8,1,IF(BO18>=0.7,0.9,IF(BO18>=0.6,0.8,IF(BO18>=0.5,0.7,IF(BO18>=0.4,0.6,IF(BO18>=0.3,0.5,IF(BO18>=0.2,0.4,IF(BO18>=0.1,0.3,0.2)))))))) | BQ18: =BP18*0.02 | BR18: =VLOOKUP(B18,'KPI Ticketing'!B:BB,53,) | BS18: =IF(BR18>=0.9,1,IF(BR18>=0.8,0.9,IF(BR18>=0.7,0.8,IF(BR18>=0.6,0.7,IF(BR18>=0.5,0.6,IF(BR18>=0.4,0.5,IF(BR18>=0.3,0.4,IF(BR18>=0.2,0.3,IF(BR18>=0.1,0.2,0.1))))))))) | BT18: =BS18*0.05 | BU18: 0.08 | BV18: 0.06 | BW18: 0.09 | BX18: 0.06
A19: R10_Sumbagteng | B19: NOP PADANG | C19: =RANK(D19,$D$10:$D$43,0) | D19: =(G19*0.35)+(O19*65%) | E19: =IF(D19>=0.95,"Istimewa",IF(D19>0.9,"Baik Sekali",IF(D19>0.85,"Baik",IF(D19>0.8,"Cukup","Kurang")))) | F19: =0.29*0.65 | G19: =N19 | H19: =VLOOKUP(B19,'KPI Availability'!B:O,14,) | I19: =VLOOKUP(B19,'KPI Availability'!B:P,15,) | J19: =VLOOKUP(B19,'KPI Availability'!B:Q,16,) | K19: =VLOOKUP(B19,'KPI Availability'!B:R,17,) | L19: =VLOOKUP(B19,'KPI Availability'!B:S,18,) | M19: =VLOOKUP(B19,'KPI Availability'!B:T,19,) | N19: =SUM(H19:M19) | O19: =P19+Q19+R19 | P19: =SUM(AA19:AD19,AG19,AJ19,AM19,AP19,AS19,AV19) | Q19: =SUM(BG19:BK19,BN19,BQ19,BT19) | R19: =SUM(BU19:BX19) | S19: =VLOOKUP(B19,'KPI Ticketing'!B:C,2,) | T19: =VLOOKUP(B19,'KPI Ticketing'!B:D,3,) | U19: =VLOOKUP(B19,'KPI Ticketing'!B:E,4,) | V19: =VLOOKUP(B19,'KPI Ticketing'!B:F,5,) | W19: =IF(S19<=4,100%,IF(S19<=6,70%,IF(S19<=8,40%,10%))) | X19: =IF(T19<=8,100%,IF(T19<=12,50%,25%)) | Y19: =IF(U19<=10,100%,IF(U19<=15,50%,25%)) | Z19: =IF(V19<=13,100%,IF(V19<=19,50%,25%)) | AA19: =W19*0.13 | AB19: =X19*0.06 | AC19: =Y19*0.04 | AD19: =Z19*0.02 | AE19: =VLOOKUP(B19,'KPI Ticketing'!B:N,13,) | AF19: =IF(AE19>=0.8,1,IF(AE19>=0.7,0.9,IF(AE19>=0.6,0.8,IF(AE19>=0.5,0.7,IF(AE19>=0.4,0.6,IF(AE19>=0.3,0.5,IF(AE19>=0.2,0.4,IF(AE19>=0.1,0.3,0.2)))))))) | AG19: =AF19*0.03 | AH19: =VLOOKUP(B19,'KPI Ticketing'!B:R,17,) | AI19: =IF(AH19>=0.8,1,IF(AH19>=0.7,0.9,IF(AH19>=0.6,0.8,IF(AH19>=0.5,0.7,IF(AH19>=0.4,0.6,IF(AH19>=0.3,0.5,IF(AH19>=0.2,0.4,IF(AH19>=0.1,0.3,0.2)))))))) | AJ19: =AI19*0.02 | AK19: =VLOOKUP(B19,'KPI Ticketing'!B:V,21,) | AL19: =IF(AK19>=0.9,1,IF(AK19>=0.8,0.9,IF(AK19>=0.7,0.8,IF(AK19>=0.6,0.7,IF(AK19>=0.5,0.6,IF(AK19>=0.4,0.5,IF(AK19>=0.3,0.4,IF(AK19>=0.2,0.3,IF(AK19>=0.1,0.2,0.1))))))))) | AM19: =AL19*0.05 | AN19: =VLOOKUP(B19,'KPI Ticketing'!B:Z,25,) | AO19: =IF(AN19>=0.95,1,IF(AN19>=0.9,0.9,IF(AN19>=0.8,0.8,IF(AN19>=0.7,0.7,IF(AN19>=0.6,0.6,IF(AN19>=0.5,0.5,IF(AN19>=0.4,0.4,IF(AN19>=0.3,0.3,IF(AN19>=0.2,0.2,IF(AN19>=0.1,0.1,0.05)))))))))) | AP19: =AO19*0.05 | AQ19: =VLOOKUP(B19,'KPI Ticketing'!B:AC,28,) | AR19: =IF(AQ19<0.95,0.5,1) | AS19: =AR19*0.01 | AT19: =VLOOKUP(B19,'KPI Ticketing'!B:AG,32,) | AU19: =IF(AT19<0.3,0.5,1) | AV19: =AU19*0.01 | AW19: =VLOOKUP(B19,'KPI Ticketing'!B:AH,33,) | AX19: =VLOOKUP(B19,'KPI Ticketing'!B:AI,34,) | AY19: =VLOOKUP(B19,'KPI Ticketing'!B:AJ,35,) | AZ19: =VLOOKUP(B19,'KPI Ticketing'!B:AK,36,) | BA19: =VLOOKUP(B19,'KPI Ticketing'!B:AL,37,) | BB19: =IF(AW19<=2,1,IF(AW19<=3,0.7,IF(AW19<=4,0.4,0.1))) | BC19: =IF(AX19<=4,1,IF(AX19<=6,0.5,0.25)) | BD19: =IF(AY19<=15,1,IF(AY19<=22.5,0.5,0.25)) | BE19: =IF(AZ19<=48,1,IF(AZ19<=72,0.5,0.25)) | BF19: =IF(BA19=0, 0, IF(BA19<=96, 1, IF(BA19<=144, 0.5, 0.25))) | BG19: =BB19*0.1 | BH19: =BC19*0.05 | BI19: =BD19*0.02 | BJ19: =BE19*0.01 | BK19: =BF19*0.01 | BL19: =VLOOKUP(B19,'KPI Ticketing'!B:AT,45,) | BM19: =IF(BL19>=0.8,1,IF(BL19>=0.7,0.9,IF(BL19>=0.6,0.8,IF(BL19>=0.5,0.7,IF(BL19>=0.4,0.6,IF(BL19>=0.3,0.5,IF(BL19>=0.2,0.4,IF(BL19>=0.1,0.3,0.2)))))))) | BN19: =BM19*0.03 | BO19: =VLOOKUP(B19,'KPI Ticketing'!B:AX,49,) | BP19: =IF(BO19>=0.8,1,IF(BO19>=0.7,0.9,IF(BO19>=0.6,0.8,IF(BO19>=0.5,0.7,IF(BO19>=0.4,0.6,IF(BO19>=0.3,0.5,IF(BO19>=0.2,0.4,IF(BO19>=0.1,0.3,0.2)))))))) | BQ19: =BP19*0.02 | BR19: =VLOOKUP(B19,'KPI Ticketing'!B:BB,53,) | BS19: =IF(BR19>=0.9,1,IF(BR19>=0.8,0.9,IF(BR19>=0.7,0.8,IF(BR19>=0.6,0.7,IF(BR19>=0.5,0.6,IF(BR19>=0.4,0.5,IF(BR19>=0.3,0.4,IF(BR19>=0.2,0.3,IF(BR19>=0.1,0.2,0.1))))))))) | BT19: =BS19*0.05 | BU19: 0.08 | BV19: 0.06 | BW19: 0.09 | BX19: 0.06
A20: R10_Sumbagteng | B20: NOP PEKANBARU | C20: =RANK(D20,$D$10:$D$43,0) | D20: =(G20*0.35)+(O20*65%) | E20: =IF(D20>=0.95,"Istimewa",IF(D20>0.9,"Baik Sekali",IF(D20>0.85,"Baik",IF(D20>0.8,"Cukup","Kurang")))) | F20: =0.29*0.65 | G20: =N20 | H20: =VLOOKUP(B20,'KPI Availability'!B:O,14,) | I20: =VLOOKUP(B20,'KPI Availability'!B:P,15,) | J20: =VLOOKUP(B20,'KPI Availability'!B:Q,16,) | K20: =VLOOKUP(B20,'KPI Availability'!B:R,17,) | L20: =VLOOKUP(B20,'KPI Availability'!B:S,18,) | M20: =VLOOKUP(B20,'KPI Availability'!B:T,19,) | N20: =SUM(H20:M20) | O20: =P20+Q20+R20 | P20: =SUM(AA20:AD20,AG20,AJ20,AM20,AP20,AS20,AV20) | Q20: =SUM(BG20:BK20,BN20,BQ20,BT20) | R20: =SUM(BU20:BX20) | S20: =VLOOKUP(B20,'KPI Ticketing'!B:C,2,) | T20: =VLOOKUP(B20,'KPI Ticketing'!B:D,3,) | U20: =VLOOKUP(B20,'KPI Ticketing'!B:E,4,) | V20: =VLOOKUP(B20,'KPI Ticketing'!B:F,5,) | W20: =IF(S20<=4,100%,IF(S20<=6,70%,IF(S20<=8,40%,10%))) | X20: =IF(T20<=8,100%,IF(T20<=12,50%,25%)) | Y20: =IF(U20<=10,100%,IF(U20<=15,50%,25%)) | Z20: =IF(V20<=13,100%,IF(V20<=19,50%,25%)) | AA20: =W20*0.13 | AB20: =X20*0.06 | AC20: =Y20*0.04 | AD20: =Z20*0.02 | AE20: =VLOOKUP(B20,'KPI Ticketing'!B:N,13,) | AF20: =IF(AE20>=0.8,1,IF(AE20>=0.7,0.9,IF(AE20>=0.6,0.8,IF(AE20>=0.5,0.7,IF(AE20>=0.4,0.6,IF(AE20>=0.3,0.5,IF(AE20>=0.2,0.4,IF(AE20>=0.1,0.3,0.2)))))))) | AG20: =AF20*0.03 | AH20: =VLOOKUP(B20,'KPI Ticketing'!B:R,17,) | AI20: =IF(AH20>=0.8,1,IF(AH20>=0.7,0.9,IF(AH20>=0.6,0.8,IF(AH20>=0.5,0.7,IF(AH20>=0.4,0.6,IF(AH20>=0.3,0.5,IF(AH20>=0.2,0.4,IF(AH20>=0.1,0.3,0.2)))))))) | AJ20: =AI20*0.02 | AK20: =VLOOKUP(B20,'KPI Ticketing'!B:V,21,) | AL20: =IF(AK20>=0.9,1,IF(AK20>=0.8,0.9,IF(AK20>=0.7,0.8,IF(AK20>=0.6,0.7,IF(AK20>=0.5,0.6,IF(AK20>=0.4,0.5,IF(AK20>=0.3,0.4,IF(AK20>=0.2,0.3,IF(AK20>=0.1,0.2,0.1))))))))) | AM20: =AL20*0.05 | AN20: =VLOOKUP(B20,'KPI Ticketing'!B:Z,25,) | AO20: =IF(AN20>=0.95,1,IF(AN20>=0.9,0.9,IF(AN20>=0.8,0.8,IF(AN20>=0.7,0.7,IF(AN20>=0.6,0.6,IF(AN20>=0.5,0.5,IF(AN20>=0.4,0.4,IF(AN20>=0.3,0.3,IF(AN20>=0.2,0.2,IF(AN20>=0.1,0.1,0.05)))))))))) | AP20: =AO20*0.05 | AQ20: =VLOOKUP(B20,'KPI Ticketing'!B:AC,28,) | AR20: =IF(AQ20<0.95,0.5,1) | AS20: =AR20*0.01 | AT20: =VLOOKUP(B20,'KPI Ticketing'!B:AG,32,) | AU20: =IF(AT20<0.3,0.5,1) | AV20: =AU20*0.01 | AW20: =VLOOKUP(B20,'KPI Ticketing'!B:AH,33,) | AX20: =VLOOKUP(B20,'KPI Ticketing'!B:AI,34,) | AY20: =VLOOKUP(B20,'KPI Ticketing'!B:AJ,35,) | AZ20: =VLOOKUP(B20,'KPI Ticketing'!B:AK,36,) | BA20: =VLOOKUP(B20,'KPI Ticketing'!B:AL,37,) | BB20: =IF(AW20<=2,1,IF(AW20<=3,0.7,IF(AW20<=4,0.4,0.1))) | BC20: =IF(AX20<=4,1,IF(AX20<=6,0.5,0.25)) | BD20: =IF(AY20<=15,1,IF(AY20<=22.5,0.5,0.25)) | BE20: =IF(AZ20<=48,1,IF(AZ20<=72,0.5,0.25)) | BF20: =IF(BA20=0, 0, IF(BA20<=96, 1, IF(BA20<=144, 0.5, 0.25))) | BG20: =BB20*0.1 | BH20: =BC20*0.05 | BI20: =BD20*0.02 | BJ20: =BE20*0.01 | BK20: =BF20*0.01 | BL20: =VLOOKUP(B20,'KPI Ticketing'!B:AT,45,) | BM20: =IF(BL20>=0.8,1,IF(BL20>=0.7,0.9,IF(BL20>=0.6,0.8,IF(BL20>=0.5,0.7,IF(BL20>=0.4,0.6,IF(BL20>=0.3,0.5,IF(BL20>=0.2,0.4,IF(BL20>=0.1,0.3,0.2)))))))) | BN20: =BM20*0.03 | BO20: =VLOOKUP(B20,'KPI Ticketing'!B:AX,49,) | BP20: =IF(BO20>=0.8,1,IF(BO20>=0.7,0.9,IF(BO20>=0.6,0.8,IF(BO20>=0.5,0.7,IF(BO20>=0.4,0.6,IF(BO20>=0.3,0.5,IF(BO20>=0.2,0.4,IF(BO20>=0.1,0.3,0.2)))))))) | BQ20: =BP20*0.02 | BR20: =VLOOKUP(B20,'KPI Ticketing'!B:BB,53,) | BS20: =IF(BR20>=0.9,1,IF(BR20>=0.8,0.9,IF(BR20>=0.7,0.8,IF(BR20>=0.6,0.7,IF(BR20>=0.5,0.6,IF(BR20>=0.4,0.5,IF(BR20>=0.3,0.4,IF(BR20>=0.2,0.3,IF(BR20>=0.1,0.2,0.1))))))))) | BT20: =BS20*0.05 | BU20: 0.08 | BV20: 0.06 | BW20: 0.09 | BX20: 0.06
A21: R02_Sumbagsel | B21: NOP BENGKULU | C21: =RANK(D21,$D$10:$D$43,0) | D21: =(G21*0.35)+(O21*65%) | E21: =IF(D21>=0.95,"Istimewa",IF(D21>0.9,"Baik Sekali",IF(D21>0.85,"Baik",IF(D21>0.8,"Cukup","Kurang")))) | F21: =0.29*0.65 | G21: =N21 | H21: =VLOOKUP(B21,'KPI Availability'!B:O,14,) | I21: =VLOOKUP(B21,'KPI Availability'!B:P,15,) | J21: =VLOOKUP(B21,'KPI Availability'!B:Q,16,) | K21: =VLOOKUP(B21,'KPI Availability'!B:R,17,) | L21: =VLOOKUP(B21,'KPI Availability'!B:S,18,) | M21: =VLOOKUP(B21,'KPI Availability'!B:T,19,) | N21: =SUM(H21:M21) | O21: =P21+Q21+R21 | P21: =SUM(AA21:AD21,AG21,AJ21,AM21,AP21,AS21,AV21) | Q21: =SUM(BG21:BK21,BN21,BQ21,BT21) | R21: =SUM(BU21:BX21) | S21: =VLOOKUP(B21,'KPI Ticketing'!B:C,2,) | T21: =VLOOKUP(B21,'KPI Ticketing'!B:D,3,) | U21: =VLOOKUP(B21,'KPI Ticketing'!B:E,4,) | V21: =VLOOKUP(B21,'KPI Ticketing'!B:F,5,) | W21: =IF(S21<=4,100%,IF(S21<=6,70%,IF(S21<=8,40%,10%))) | X21: =IF(T21<=8,100%,IF(T21<=12,50%,25%)) | Y21: =IF(U21<=10,100%,IF(U21<=15,50%,25%)) | Z21: =IF(V21<=13,100%,IF(V21<=19,50%,25%)) | AA21: =W21*0.13 | AB21: =X21*0.06 | AC21: =Y21*0.04 | AD21: =Z21*0.02 | AE21: =VLOOKUP(B21,'KPI Ticketing'!B:N,13,) | AF21: =IF(AE21>=0.8,1,IF(AE21>=0.7,0.9,IF(AE21>=0.6,0.8,IF(AE21>=0.5,0.7,IF(AE21>=0.4,0.6,IF(AE21>=0.3,0.5,IF(AE21>=0.2,0.4,IF(AE21>=0.1,0.3,0.2)))))))) | AG21: =AF21*0.03 | AH21: =VLOOKUP(B21,'KPI Ticketing'!B:R,17,) | AI21: =IF(AH21>=0.8,1,IF(AH21>=0.7,0.9,IF(AH21>=0.6,0.8,IF(AH21>=0.5,0.7,IF(AH21>=0.4,0.6,IF(AH21>=0.3,0.5,IF(AH21>=0.2,0.4,IF(AH21>=0.1,0.3,0.2)))))))) | AJ21: =AI21*0.02 | AK21: =VLOOKUP(B21,'KPI Ticketing'!B:V,21,) | AL21: =IF(AK21>=0.9,1,IF(AK21>=0.8,0.9,IF(AK21>=0.7,0.8,IF(AK21>=0.6,0.7,IF(AK21>=0.5,0.6,IF(AK21>=0.4,0.5,IF(AK21>=0.3,0.4,IF(AK21>=0.2,0.3,IF(AK21>=0.1,0.2,0.1))))))))) | AM21: =AL21*0.05 | AN21: =VLOOKUP(B21,'KPI Ticketing'!B:Z,25,) | AO21: =IF(AN21>=0.95,1,IF(AN21>=0.9,0.9,IF(AN21>=0.8,0.8,IF(AN21>=0.7,0.7,IF(AN21>=0.6,0.6,IF(AN21>=0.5,0.5,IF(AN21>=0.4,0.4,IF(AN21>=0.3,0.3,IF(AN21>=0.2,0.2,IF(AN21>=0.1,0.1,0.05)))))))))) | AP21: =AO21*0.05 | AQ21: =VLOOKUP(B21,'KPI Ticketing'!B:AC,28,) | AR21: =IF(AQ21<0.95,0.5,1) | AS21: =AR21*0.01 | AT21: =VLOOKUP(B21,'KPI Ticketing'!B:AG,32,) | AU21: =IF(AT21<0.3,0.5,1) | AV21: =AU21*0.01 | AW21: =VLOOKUP(B21,'KPI Ticketing'!B:AH,33,) | AX21: =VLOOKUP(B21,'KPI Ticketing'!B:AI,34,) | AY21: =VLOOKUP(B21,'KPI Ticketing'!B:AJ,35,) | AZ21: =VLOOKUP(B21,'KPI Ticketing'!B:AK,36,) | BA21: =VLOOKUP(B21,'KPI Ticketing'!B:AL,37,) | BB21: =IF(AW21<=2,1,IF(AW21<=3,0.7,IF(AW21<=4,0.4,0.1))) | BC21: =IF(AX21<=4,1,IF(AX21<=6,0.5,0.25)) | BD21: =IF(AY21<=15,1,IF(AY21<=22.5,0.5,0.25)) | BE21: =IF(AZ21<=48,1,IF(AZ21<=72,0.5,0.25)) | BF21: =IF(BA21=0, 0, IF(BA21<=96, 1, IF(BA21<=144, 0.5, 0.25))) | BG21: =BB21*0.1 | BH21: =BC21*0.05 | BI21: =BD21*0.02 | BJ21: =BE21*0.01 | BK21: =BF21*0.01 | BL21: =VLOOKUP(B21,'KPI Ticketing'!B:AT,45,) | BM21: =IF(BL21>=0.8,1,IF(BL21>=0.7,0.9,IF(BL21>=0.6,0.8,IF(BL21>=0.5,0.7,IF(BL21>=0.4,0.6,IF(BL21>=0.3,0.5,IF(BL21>=0.2,0.4,IF(BL21>=0.1,0.3,0.2)))))))) | BN21: =BM21*0.03 | BO21: =VLOOKUP(B21,'KPI Ticketing'!B:AX,49,) | BP21: =IF(BO21>=0.8,1,IF(BO21>=0.7,0.9,IF(BO21>=0.6,0.8,IF(BO21>=0.5,0.7,IF(BO21>=0.4,0.6,IF(BO21>=0.3,0.5,IF(BO21>=0.2,0.4,IF(BO21>=0.1,0.3,0.2)))))))) | BQ21: =BP21*0.02 | BR21: =VLOOKUP(B21,'KPI Ticketing'!B:BB,53,) | BS21: =IF(BR21>=0.9,1,IF(BR21>=0.8,0.9,IF(BR21>=0.7,0.8,IF(BR21>=0.6,0.7,IF(BR21>=0.5,0.6,IF(BR21>=0.4,0.5,IF(BR21>=0.3,0.4,IF(BR21>=0.2,0.3,IF(BR21>=0.1,0.2,0.1))))))))) | BT21: =BS21*0.05 | BU21: 0.08 | BV21: 0.06 | BW21: 0.09 | BX21: 0.06
... A43: R07_Bali Nusra | B43: NOP MATARAM | C43: =RANK(D43,$D$10:$D$43,0) | D43: =(G43*0.35)+(O43*65%) | E43: =IF(D43>=0.95,"Istimewa",IF(D43>0.9,"Baik Sekali",IF(D43>0.85,"Baik",IF(D43>0.8,"Cukup","Kurang")))) | F43: =0.29*0.65 | G43: =N43 | H43: =VLOOKUP(B43,'KPI Availability'!B:O,14,) | I43: =VLOOKUP(B43,'KPI Availability'!B:P,15,) | J43: =VLOOKUP(B43,'KPI Availability'!B:Q,16,) | K43: =VLOOKUP(B43,'KPI Availability'!B:R,17,) | L43: =VLOOKUP(B43,'KPI Availability'!B:S,18,) | M43: =VLOOKUP(B43,'KPI Availability'!B:T,19,) | N43: =SUM(H43:M43) | O43: =P43+Q43+R43 | P43: =SUM(AA43:AD43,AG43,AJ43,AM43,AP43,AS43,AV43) | Q43: =SUM(BG43:BK43,BN43,BQ43,BT43) | R43: =SUM(BU43:BX43) | S43: =VLOOKUP(B43,'KPI Ticketing'!B:C,2,) | T43: =VLOOKUP(B43,'KPI Ticketing'!B:D,3,) | U43: =VLOOKUP(B43,'KPI Ticketing'!B:E,4,) | V43: =VLOOKUP(B43,'KPI Ticketing'!B:F,5,) | W43: =IF(S43<=4,100%,IF(S43<=6,70%,IF(S43<=8,40%,10%))) | X43: =IF(T43<=8,100%,IF(T43<=12,50%,25%)) | Y43: =IF(U43<=10,100%,IF(U43<=15,50%,25%)) | Z43: =IF(V43<=13,100%,IF(V43<=19,50%,25%)) | AA43: =W43*0.13 | AB43: =X43*0.06 | AC43: =Y43*0.04 | AD43: =Z43*0.02 | AE43: =VLOOKUP(B43,'KPI Ticketing'!B:N,13,) | AF43: =IF(AE43>=0.8,1,IF(AE43>=0.7,0.9,IF(AE43>=0.6,0.8,IF(AE43>=0.5,0.7,IF(AE43>=0.4,0.6,IF(AE43>=0.3,0.5,IF(AE43>=0.2,0.4,IF(AE43>=0.1,0.3,0.2)))))))) | AG43: =AF43*0.03 | AH43: =VLOOKUP(B43,'KPI Ticketing'!B:R,17,) | AI43: =IF(AH43>=0.8,1,IF(AH43>=0.7,0.9,IF(AH43>=0.6,0.8,IF(AH43>=0.5,0.7,IF(AH43>=0.4,0.6,IF(AH43>=0.3,0.5,IF(AH43>=0.2,0.4,IF(AH43>=0.1,0.3,0.2)))))))) | AJ43: =AI43*0.02 | AK43: =VLOOKUP(B43,'KPI Ticketing'!B:V,21,) | AL43: =IF(AK43>=0.9,1,IF(AK43>=0.8,0.9,IF(AK43>=0.7,0.8,IF(AK43>=0.6,0.7,IF(AK43>=0.5,0.6,IF(AK43>=0.4,0.5,IF(AK43>=0.3,0.4,IF(AK43>=0.2,0.3,IF(AK43>=0.1,0.2,0.1))))))))) | AM43: =AL43*0.05 | AN43: =VLOOKUP(B43,'KPI Ticketing'!B:Z,25,) | AO43: =IF(AN43>=0.95,1,IF(AN43>=0.9,0.9,IF(AN43>=0.8,0.8,IF(AN43>=0.7,0.7,IF(AN43>=0.6,0.6,IF(AN43>=0.5,0.5,IF(AN43>=0.4,0.4,IF(AN43>=0.3,0.3,IF(AN43>=0.2,0.2,IF(AN43>=0.1,0.1,0.05)))))))))) | AP43: =AO43*0.05 | AQ43: =VLOOKUP(B43,'KPI Ticketing'!B:AC,28,) | AR43: =IF(AQ43<0.95,0.5,1) | AS43: =AR43*0.01 | AT43: =VLOOKUP(B43,'KPI Ticketing'!B:AG,32,) | AU43: =IF(AT43<0.3,0.5,1) | AV43: =AU43*0.01 | AW43: =VLOOKUP(B43,'KPI Ticketing'!B:AH,33,) | AX43: =VLOOKUP(B43,'KPI Ticketing'!B:AI,34,) | AY43: =VLOOKUP(B43,'KPI Ticketing'!B:AJ,35,) | AZ43: =VLOOKUP(B43,'KPI Ticketing'!B:AK,36,) | BA43: =VLOOKUP(B43,'KPI Ticketing'!B:AL,37,) | BB43: =IF(AW43<=2,1,IF(AW43<=3,0.7,IF(AW43<=4,0.4,0.1))) | BC43: =IF(AX43<=4,1,IF(AX43<=6,0.5,0.25)) | BD43: =IF(AY43<=15,1,IF(AY43<=22.5,0.5,0.25)) | BE43: =IF(AZ43<=48,1,IF(AZ43<=72,0.5,0.25)) | BF43: =IF(BA43=0, 0, IF(BA43<=96, 1, IF(BA43<=144, 0.5, 0.25))) | BG43: =BB43*0.1 | BH43: =BC43*0.05 | BI43: =BD43*0.02 | BJ43: =BE43*0.01 | BK43: =BF43*0.01 | BL43: =VLOOKUP(B43,'KPI Ticketing'!B:AT,45,) | BM43: =IF(BL43>=0.8,1,IF(BL43>=0.7,0.9,IF(BL43>=0.6,0.8,IF(BL43>=0.5,0.7,IF(BL43>=0.4,0.6,IF(BL43>=0.3,0.5,IF(BL43>=0.2,0.4,IF(BL43>=0.1,0.3,0.2)))))))) | BN43: =BM43*0.03 | BO43: =VLOOKUP(B43,'KPI Ticketing'!B:AX,49,) | BP43: =IF(BO43>=0.8,1,IF(BO43>=0.7,0.9,IF(BO43>=0.6,0.8,IF(BO43>=0.5,0.7,IF(BO43>=0.4,0.6,IF(BO43>=0.3,0.5,IF(BO43>=0.2,0.4,IF(BO43>=0.1,0.3,0.2)))))))) | BQ43: =BP43*0.02 | BR43: =VLOOKUP(B43,'KPI Ticketing'!B:BB,53,) | BS43: =IF(BR43>=0.9,1,IF(BR43>=0.8,0.9,IF(BR43>=0.7,0.8,IF(BR43>=0.6,0.7,IF(BR43>=0.5,0.6,IF(BR43>=0.4,0.5,IF(BR43>=0.3,0.4,IF(BR43>=0.2,0.3,IF(BR43>=0.1,0.2,0.1))))))))) | BT43: =BS43*0.05 | BU43: 0.08 | BV43: 0.06 | BW43: 0.09 | BX43: 0.06

Sheet KPI Availability

Sheet KPI Ticketing
A1: Regional | B1: NOP | C1: IM-MTTRP90-Critical | D1: IM-MTTRP90-Major | E1: IM-MTTRP90-Minor | F1: IM-MTTRP90-Low | G1: IM-unTO | H1: IM-TO | I1: IM-TO-Total | J1: IM-%TO | K1: IM-unTO-High | L1: IM-TO-High | M1: IM-High-Total | N1: IM-High-%TO | O1: IM-unTO-Low | P1: IM-TO-Low | Q1: IM-Low-Total | R1: IM-Low-%TO | S1: IM-NoVisit | T1: IM-Visit | U1: IM-Visitation | V1: IM-%Visit | W1: IM-Top5-NoVisit | X1: IM-Top5-Visit | Y1: IM-Top5-Total | Z1: IM-%Top5 | AA1: IM-Closing | AB1: IM-Total_x | AC1: IM-%Closing | AD1: IM-NoRCA | AE1: IM-RCA | AF1: IM-Total_y | AG1: IM-%RCA | AH1: EM-MTTRP90-Critical | AI1: EM-MTTRP90-Major | AJ1: EM-MTTRP90-Minor | AK1: EM-MTTRP90-Low | AL1: EM-MTTRP90-Very Low | AM1: EM-AutoClear | AN1: EM-Takeover | AO1: EM_Total_Takeover | AP1: EM_Percent_Takeover | AQ1: EM-unTO-High | AR1: EM-TO-High | AS1: EM-High-Total | AT1: EM-High-%TO | AU1: EM-unTO-Low | AV1: EM-TO-Low | AW1: EM-Low-Total | AX1: EM-Low-%TO | AY1: EM-NoVisit | AZ1: EM-Visit | BA1: EM-Visitation-Total | BB1: EM-%Visit
A2: R01_Sumbagut | B2: NOP ACEH | C2: 3.68 | D2: 4.826 | E2: 9.4 | F2: 10.001 | G2: 471 | H2: 2606 | I2: 3077 | J2: 0.84692883 | K2: 127 | L2: 627 | M2: 754 | N2: 0.83156499 | O2: 344 | P2: 1979 | Q2: 2323 | R2: 0.85191563 | S2: 358 | T2: 269 | U2: 627 | V2: 0.42902711 | W2: 354 | X2: 268 | Y2: 622 | Z2: 0.43086817 | AA2: 3076 | AB2: 3077 | AC2: 0.99967501 | AD2: 2068 | AE2: 1009 | AF2: 3077 | AG2: 0.3279168 | AH2: 0.06 | AI2: 4.804 | AJ2: 69.11 | AK2: 128.152 | AL2: 0 | AM2: 1314 | AN2: 9245 | AO2: 10559 | AP2: 0.8755564 | AQ2: 405 | AR2: 1073 | AS2: 1478 | AT2: 0.72598106 | AU2: 880 | AV2: 8110 | AW2: 8990 | AX2: 0.90211346 | AY2: 840 | AZ2: 233 | BA2: 1073 | BB2: 0.21714818
A3: R01_Sumbagut | B3: NOP BINJAI | C3: 9.9 | D3: 4.064 | E3: 4.28 | F3: 4.279 | G3: 473 | H3: 890 | I3: 1363 | J3: 0.65297139 | K3: 72 | L3: 238 | M3: 310 | N3: 0.76774194 | O3: 401 | P3: 652 | Q3: 1053 | R3: 0.61918329 | S3: 108 | T3: 130 | U3: 238 | V3: 0.54621849 | W3: 108 | X3: 129 | Y3: 237 | Z3: 0.5443038 | AA3: 1363 | AB3: 1363 | AC3: 1 | AD3: 875 | AE3: 488 | AF3: 1363 | AG3: 0.35803375 | AH3: 0.02 | AI3: 2.729 | AJ3: 35.371 | AK3: 117.42 | AL3: 0 | AM3: 898 | AN3: 1828 | AO3: 2726 | AP3: 0.6705796 | AQ3: 359 | AR3: 462 | AS3: 821 | AT3: 0.56272838 | AU3: 469 | AV3: 1314 | AW3: 1783 | AX3: 0.73696018 | AY3: 203 | AZ3: 259 | BA3: 462 | BB3: 0.56060606
A4: R01_Sumbagut | B4: NOP MEDAN | C4: 4.649 | D4: 4.097 | E4: 4.608 | F4: 5.029 | G4: 944 | H4: 587 | I4: 1531 | J4: 0.38340954 | K4: 286 | L4: 222 | M4: 508 | N4: 0.43700787 | O4: 658 | P4: 365 | Q4: 1023 | R4: 0.35679374 | S4: 49 | T4: 173 | U4: 222 | V4: 0.77927928 | W4: 46 | X4: 172 | Y4: 218 | Z4: 0.78899083 | AA4: 1528 | AB4: 1531 | AC4: 0.9980405 | AD4: 1168 | AE4: 363 | AF4: 1531 | AG4: 0.23709993 | AH4: 0 | AI4: 5.385 | AJ4: 19.412 | AK4: 8.646 | AL4: 0 | AM4: 1032 | AN4: 488 | AO4: 1520 | AP4: 0.32105263 | AQ4: 336 | AR4: 80 | AS4: 416 | AT4: 0.19230769 | AU4: 595 | AV4: 394 | AW4: 989 | AX4: 0.3983822 | AY4: 12 | AZ4: 68 | BA4: 80 | BB4: 0.85
A5: R01_Sumbagut | B5: NOP PADANG SIDEMPUAN | C5: 3.08 | D5: 4.154 | E5: 4.86 | F5: 6.385 | G5: 1647 | H5: 733 | I5: 2380 | J5: 0.30798319 | K5: 177 | L5: 145 | M5: 322 | N5: 0.45031056 | O5: 1470 | P5: 588 | Q5: 2058 | R5: 0.28571429 | S5: 81 | T5: 64 | U5: 145 | V5: 0.44137931 | W5: 81 | X5: 64 | Y5: 145 | Z5: 0.44137931 | AA5: 2367 | AB5: 2380 | AC5: 0.99453782 | AD5: 2078 | AE5: 302 | AF5: 2380 | AG5: 0.12689076 | AH5: 0.01 | AI5: 2.646 | AJ5: 12.462 | AK5: 98.808 | AL5: 0 | AM5: 6020 | AN5: 2513 | AO5: 8533 | AP5: 0.29450369 | AQ5: 1265 | AR5: 893 | AS5: 2158 | AT5: 0.41380908 | AU5: 4699 | AV5: 1611 | AW5: 6310 | AX5: 0.25530903 | AY5: 471 | AZ5: 422 | BA5: 893 | BB5: 0.47256439
A6: R01_Sumbagut | B6: NOP PEMATANG SIANTAR | C6: 3.66 | D6: 4.132 | E6: 5.337 | F6: 5.205 | G6: 2264 | H6: 1100 | I6: 3364 | J6: 0.32699168 | K6: 583 | L6: 353 | M6: 936 | N6: 0.37713675 | O6: 1681 | P6: 747 | Q6: 2428 | R6: 0.30766063 | S6: 115 | T6: 238 | U6: 353 | V6: 0.67422096 | W6: 110 | X6: 233 | Y6: 343 | Z6: 0.67930029 | AA6: 3347 | AB6: 3364 | AC6: 0.99494649 | AD6: 2736 | AE6: 628 | AF6: 3364 | AG6: 0.18668252 | AH6: 0.03 | AI6: 4.434 | AJ6: 71.42 | AK6: 74.16 | AL6: 0 | AM6: 12511 | AN6: 1604 | AO6: 14115 | AP6: 0.11363797 | AQ6: 897 | AR6: 436 | AS6: 1333 | AT6: 0.32708177 | AU6: 11510 | AV6: 1129 | AW6: 12639 | AX6: 0.089326687 | AY6: 66 | AZ6: 370 | BA6: 436 | BB6: 0.84862385
A7: R01_Sumbagut | B7: NOP RANTAU PRAPAT | C7: 5.12 | D7: 6.219 | E7: 5.59 | F7: 5.29 | G7: 3494 | H7: 1506 | I7: 5000 | J7: 0.3012 | K7: 583 | L7: 276 | M7: 859 | N7: 0.32130384 | O7: 2911 | P7: 1230 | Q7: 4141 | R7: 0.2970297 | S7: 100 | T7: 176 | U7: 276 | V7: 0.63768116 | W7: 99 | X7: 176 | Y7: 275 | Z7: 0.64 | AA7: 4951 | AB7: 5000 | AC7: 0.9902 | AD7: 4120 | AE7: 880 | AF7: 5000 | AG7: 0.176 | AH7: 0.03 | AI7: 4.291 | AJ7: 36.677 | AK7: 50.25 | AL7: 0 | AM7: 8995 | AN7: 673 | AO7: 9668 | AP7: 0.069611088 | AQ7: 1027 | AR7: 203 | AS7: 1230 | AT7: 0.16504065 | AU7: 7753 | AV7: 392 | AW7: 8145 | AX7: 0.048127686 | AY7: 75 | AZ7: 128 | BA7: 203 | BB7: 0.63054187
A8: R10_Sumbagteng | B8: NOP BATAM | C8: 3.076 | D8: 10.46 | E8: 6.884 | F8: 9.693 | G8: 2720 | H8: 1064 | I8: 3784 | J8: 0.28118393 | K8: 480 | L8: 214 | M8: 694 | N8: 0.30835735 | O8: 2240 | P8: 850 | Q8: 3090 | R8: 0.27508091 | S8: 85 | T8: 129 | U8: 214 | V8: 0.60280374 | W8: 80 | X8: 129 | Y8: 209 | Z8: 0.61722488 | AA8: 3759 | AB8: 3784 | AC8: 0.99339323 | AD8: 3119 | AE8: 665 | AF8: 3784 | AG8: 0.17573996 | AH8: 0.127 | AI8: 5.606 | AJ8: 37.128 | AK8: 23.56 | AL8: 0 | AM8: 11482 | AN8: 1005 | AO8: 12487 | AP8: 0.080483703 | AQ8: 1389 | AR8: 404 | AS8: 1793 | AT8: 0.22532069 | AU8: 9981 | AV8: 587 | AW8: 10568 | AX8: 0.055545042 | AY8: 78 | AZ8: 326 | BA8: 404 | BB8: 0.80693069
A9: R10_Sumbagteng | B9: NOP BUKITTINGGI | C9: 2.46 | D9: 4.245 | E9: 4.916 | F9: 5.88 | G9: 348 | H9: 1078 | I9: 1426 | J9: 0.75596073 | K9: 55 | L9: 285 | M9: 340 | N9: 0.83823529 | O9: 293 | P9: 793 | Q9: 1086 | R9: 0.73020258 | S9: 94 | T9: 191 | U9: 285 | V9: 0.67017544 | W9: 87 | X9: 186 | Y9: 273 | Z9: 0.68131868 | AA9: 1402 | AB9: 1426 | AC9: 0.98316971 | AD9: 776 | AE9: 650 | AF9: 1426 | AG9: 0.45582048 | AH9: 0.06 | AI9: 3.75 | AJ9: 13.044 | AK9: 102.086 | AL9: 0 | AM9: 5498 | AN9: 2202 | AO9: 7700 | AP9: 0.28597403 | AQ9: 119 | AR9: 470 | AS9: 589 | AT9: 0.79796265 | AU9: 5323 | AV9: 1716 | AW9: 7039 | AX9: 0.24378463 | AY9: 199 | AZ9: 271 | BA9: 470 | BB9: 0.57659574
A10: R10_Sumbagteng | B10: NOP DUMAI | C10: 4.66 | D10: 5.6 | E10: 5.69 | F10: 7.45 | G10: 3107 | H10: 2296 | I10: 5403 | J10: 0.4249491 | K10: 694 | L10: 772 | M10: 1466 | N10: 0.526603 | O10: 2413 | P10: 1524 | Q10: 3937 | R10: 0.38709677 | S10: 208 | T10: 564 | U10: 772 | V10: 0.73056995 | W10: 192 | X10: 543 | Y10: 735 | Z10: 0.73877551 | AA10: 5278 | AB10: 5403 | AC10: 0.9768647 | AD10: 4063 | AE10: 1340 | AF10: 5403 | AG10: 0.24801036 | AH10: 0.17 | AI10: 4.65 | AJ10: 57.655 | AK10: 133.945 | AL10: 0 | AM10: 7136 | AN10: 3015 | AO10: 10151 | AP10: 0.29701507 | AQ10: 1385 | AR10: 742 | AS10: 2127 | AT10: 0.34884814 | AU10: 5387 | AV10: 2247 | AW10: 7634 | AX10: 0.29434111 | AY10: 47 | AZ10: 695 | BA10: 742 | BB10: 0.93665768
A11: R10_Sumbagteng | B11: NOP PADANG | C11: 3.661 | D11: 2.77 | E11: 6.21 | F11: 6.74 | G11: 561 | H11: 1521 | I11: 2082 | J11: 0.73054755 | K11: 72 | L11: 173 | M11: 245 | N11: 0.70612245 | O11: 489 | P11: 1348 | Q11: 1837 | R11: 0.73380512 | S11: 85 | T11: 88 | U11: 173 | V11: 0.50867052 | W11: 85 | X11: 88 | Y11: 173 | Z11: 0.50867052 | AA11: 2051 | AB11: 2082 | AC11: 0.98511047 | AD11: 1488 | AE11: 594 | AF11: 2082 | AG11: 0.28530259 | AH11: 0.06 | AI11: 4.678 | AJ11: 37.191 | AK11: 60.467 | AL11: 0 | AM11: 2320 | AN11: 7260 | AO11: 9580 | AP11: 0.75782881 | AQ11: 357 | AR11: 716 | AS11: 1073 | AT11: 0.66728798 | AU11: 1924 | AV11: 6500 | AW11: 8424 | AX11: 0.77160494 | AY11: 342 | AZ11: 374 | BA11: 716 | BB11: 0.52234637
A12: R10_Sumbagteng | B12: NOP PEKANBARU | C12: 5.892 | D12: 5.841 | E12: 5.99 | F12: 7.738 | G12: 3025 | H12: 2305 | I12: 5330 | J12: 0.43245779 | K12: 420 | L12: 483 | M12: 903 | N12: 0.53488372 | O12: 2605 | P12: 1822 | Q12: 4427 | R12: 0.41156539 | S12: 119 | T12: 364 | U12: 483 | V12: 0.75362319 | W12: 116 | X12: 363 | Y12: 479 | Z12: 0.75782881 | AA12: 5266 | AB12: 5330 | AC12: 0.9879925 | AD12: 4079 | AE12: 1251 | AF12: 5330 | AG12: 0.23470919 | AH12: 0.03 | AI12: 3.376 | AJ12: 49.13 | AK12: 100.257 | AL12: 0 | AM12: 6113 | AN12: 2668 | AO12: 8781 | AP12: 0.30383783 | AQ12: 1819 | AR12: 834 | AS12: 2653 | AT12: 0.3143611 | AU12: 3963 | AV12: 1781 | AW12: 5744 | AX12: 0.31006267 | AY12: 149 | AZ12: 685 | BA12: 834 | BB12: 0.82134293
A13: R02_Sumbagsel | B13: NOP BENGKULU | C13: 2.71 | D13: 5.34 | E13: 5.295 | F13: 6.822 | G13: 2356 | H13: 1227 | I13: 3583 | J13: 0.34245046 | K13: 571 | L13: 421 | M13: 992 | N13: 0.42439516 | O13: 1785 | P13: 806 | Q13: 2591 | R13: 0.3110768 | S13: 172 | T13: 249 | U13: 421 | V13: 0.59144893 | W13: 150 | X13: 249 | Y13: 399 | Z13: 0.62406015 | AA13: 3540 | AB13: 3583 | AC13: 0.98799888 | AD13: 2959 | AE13: 624 | AF13: 3583 | AG13: 0.17415574 | AH13: 0 | AI13: 6.57 | AJ13: 7.57 | AK13: 10.984 | AL13: 0 | AM13: 3459 | AN13: 2730 | AO13: 6189 | AP13: 0.44110519 | AQ13: 2569 | AR13: 1551 | AS13: 4120 | AT13: 0.37645631 | AU13: 647 | AV13: 941 | AW13: 1588 | AX13: 0.59256927 | AY13: 198 | AZ13: 1353 | BA13: 1551 | BB13: 0.87234043
... A35: R07_Bali Nusra | B35: NOP MATARAM | C35: 5.424 | D35: 5.75 | E35: 5.3 | F35: 5.82 | G35: 379 | H35: 467 | I35: 846 | J35: 0.55200946 | K35: 42 | L35: 79 | M35: 121 | N35: 0.65289256 | O35: 337 | P35: 388 | Q35: 725 | R35: 0.53517241 | S35: 23 | T35: 56 | U35: 79 | V35: 0.70886076 | W35: 23 | X35: 56 | Y35: 79 | Z35: 0.70886076 | AA35: 838 | AB35: 846 | AC35: 0.99054374 | AD35: 560 | AE35: 286 | AF35: 846 | AG35: 0.33806147 | AH35: 0.906 | AI35: 24.044 | AJ35: 20.136 | AK35: 81.025 | AL35: 0 | AM35: 997 | AN35: 653 | AO35: 1650 | AP35: 0.39575758 | AQ35: 576 | AR35: 413 | AS35: 989 | AT35: 0.41759353 | AU35: 421 | AV35: 240 | AW35: 661 | AX35: 0.36308623 | AY35: 160 | AZ35: 253 | BA35: 413 | BB35: 0.6125908

Sheet Daily
A1: Date | B1: Regional | C1: NOP | D1: IM-MTTRP90-Critical-Daily | E1: IM-MTTRP90-Major-Daily | F1: IM-MTTRP90-Minor-Daily | G1: IM-MTTRP90-Low-Daily | H1: IM-TO-Daily | I1: IM-%TO-Daily | J1: IM-TO-High-Daily | K1: IM-%TO-High-Daily | L1: IM-TO-Low-Daily | M1: IM-%TO-Low-Daily | N1: IM-Visit-Daily | O1: IM-%Visit-Daily | P1: IM-Top5Visit-Daily | Q1: IM-%Top5-Daily | R1: IM-Closed-Daily | S1: IM-%Closing-Daily | T1: IM-RCA-Daily | U1: IM-%RCAValidation-Daily | V1: EM-MTTRP90-Critical-Daily | W1: EM-MTTRP90-Major-Daily | X1: EM-MTTRP90-Minor-Daily | Y1: EM-MTTRP90-Low-Daily | Z1: EM-MTTRP90-Very Low-Daily | AA1: EM-TO-Daily | AB1: EM-%TO-Daily | AC1: EM-TO-High-Daily | AD1: EM-%TO-High-Daily | AE1: EM-TO-Low-Daily | AF1: EM-%TO-Low-Daily | AG1: EM-Visit-Daily | AH1: EM-%Visit-Daily
A2: 45748 | B2: R01_Sumbagut | C2: NOP ACEH | D2: 2.45 | E2: 3.482 | F2: 2.254 | G2: 5.138 | H2: 100 | I2: 0.88495575 | J2: 27 | K2: 1 | L2: 73 | M2: 0.84883721 | N2: 11 | O2: 0.40740741 | P2: 11 | Q2: 0.40740741 | R2: 113 | S2: 1 | T2: 31 | U2: 0.27433628 | V2: 0 | W2: 3.96 | X2: 85.096 | Y2: 113.4 | Z2: 0 | AA2: 289 | AB2: 0.86011905 | AC2: 27 | AD2: 0.87096774 | AE2: 262 | AF2: 0.85901639 | AG2: 6 | AH2: 0.22222222
